Workbook

Sheet Final Report
C9: ='Totals Non-Residential'!F98 -> 0 | G9: kWh/yr | J9: of total building energy reduction compared to minimum BCA 2022 Compliance.
D15: ='Totals Non-Residential'!K79 -> #DIV/0! | F15: GHG emission | L15: reduction in the whole building compared to minimum BCA 2022 Compliance.
D24: ='Totals Non-Residential'!T79 -> 0 | I24: of operating cost reduction per apartment per year compared to minimum BCA 2022 Compliance.
T25: *All results are indicative only, based on preliminary assumptions.

Sheet Inputs Non-Residential
B3: Development | G3: Location
C5: Development Address | H5: Climate zone | I5: 6
C6: Retail | E6: m2
C7: Office | E7: m2
C8: Student Accomodation | E8: m2 | F8: No. Beds
C9: Educational | E9: m2
C10: Aged Care | E10: m2 | F10: No. Beds
C11: Carpark | E11: m2
C12: Services | E12: m2
C13: No. of Lifts
C14: Lift Height | E14: m
C16: Carbon Neutral
B20: Energy
C22: Retail | H22: Office | L22: Student Accomodation | P22: Educational | T22: Aged Care
C23: % reduction on DTS compliance (heating & cooling only) | D23: 2 | E23: % | H23: % reduction on DTS compliance (heating & cooling only) | J23: % | L23: % reduction on DTS compliance (heating & cooling only) | M23: 0 | N23: % | P23: % reduction on DTS compliance (heating & cooling only) | R23: % | T23: % reduction on DTS compliance (heating & cooling only) | V23: %
C24: Type of HVAC system | D24: VRV/VRF | H24: Type of HVAC system | I24: VRV/VRF | L24: Type of HVAC system | M24: VRV/VRF | P24: Type of HVAC system | Q24: VRV/VRF | T24: Type of HVAC system | U24: VRV/VRF
C25: Efficency of HVAC system | D25: =VLOOKUP(D24,Table13[#All],2,FALSE) -> 3.4 | E25: COP | H25: Efficency of HVAC system | I25: =VLOOKUP(I24,Table13[#All],2,FALSE) -> 3.4 | J25: COP | L25: Efficency of HVAC system | M25: =VLOOKUP(M24,Table13[#All],2,FALSE) -> 3.4 | N25: COP | P25: Efficency of HVAC system | Q25: =VLOOKUP(Q24,Table13[#All],2,FALSE) -> 3.4 | R25: COP | T25: Efficency of HVAC system | U25: =VLOOKUP(U24,Table13[#All],2,FALSE) -> 3.4 | V25: COP
C26: % reduction on lighting power | D26: 0 | E26: % | H26: % reduction on lighting power | I26: 0 | J26: % | L26: % reduction on lighting power | M26: 0 | N26: % | P26: % reduction on lighting power | Q26: 0 | R26: % | T26: % reduction on lighting power | U26: 0 | V26: %
C27: Cooktops | D27: None | L27: Cooktops | M27: None | P27: Cooktops | Q27: None | T27: Cooktops | U27: None
H28: OR
C29: OR
C31: J1V3 Modelling Results | H31: J1V3 Modelling Results | L31: J1V3 Modelling Results | P31: J1V3 Modelling Results | T31: J1V3 Modelling Results
C32: Reference Heating Energy Use (Elec) | E32: kWh/m2 | H32: Reference Heating Energy Use (Elec) | J32: kWh/m2 | L32: Reference Heating Energy Use (Elec) | N32: kWh/m2 | P32: Reference Heating Energy Use (Elec) | R32: kWh/m2 | T32: Reference Heating Energy Use (Elec) | V32: kWh/m2
C33: Reference Cooling Energy Use (Elec) | E33: kWh/m2 | H33: Reference Cooling Energy Use (Elec) | J33: kWh/m2 | L33: Reference Cooling Energy Use (Elec) | N33: kWh/m2 | P33: Reference Cooling Energy Use (Elec) | R33: kWh/m2 | T33: Reference Cooling Energy Use (Elec) | V33: kWh/m2
C34: Reference Heating Energy Use (Gas) | E34: MJ/m2 | H34: Reference Heating Energy Use (Gas) | J34: MJ/m2 | L34: Reference Heating Energy Use (Gas) | M34: 1000 | N34: MJ/m2 | P34: Reference Heating Energy Use (Gas) | R34: MJ/m2 | T34: Reference Heating Energy Use (Gas) | V34: MJ/m2
C35: Reference Cooling Energy Use (Gas) | E35: MJ/m2 | H35: Reference Cooling Energy Use (Gas) | J35: MJ/m2 | L35: Reference Cooling Energy Use (Gas) | M35: 750 | N35: MJ/m2 | P35: Reference Cooling Energy Use (Gas) | R35: MJ/m2 | T35: Reference Cooling Energy Use (Gas) | V35: MJ/m2
C36: Reference Fans | E36: kWh/m2 | H36: Reference Fans | J36: kWh/m2 | L36: Reference Fans | N36: kWh/m2 | P36: Reference Fans | R36: kWh/m2 | T36: Reference Fans | V36: kWh/m2
C37: Reference Lighting | E37: kWh/m2 | H37: Reference Lighting | J37: kWh/m2 | L37: Reference Lighting | N37: kWh/m2 | P37: Reference Lighting | R37: kWh/m2 | T37: Reference Lighting | V37: kWh/m2
C39: Proposed Heating Energy Use (Elec) | E39: kWh/m2 | H39: Proposed Heating Energy Use (Elec) | J39: kWh/m2 | L39: Proposed Heating Energy Use (Elec) | N39: kWh/m2 | P39: Proposed Heating Energy Use (Elec) | R39: kWh/m2 | T39: Proposed Heating Energy Use (Elec) | V39: kWh/m2
C40: Proposed Cooling Energy Use (Elec) | E40: kWh/m2 | H40: Proposed Cooling Energy Use (Elec) | J40: kWh/m2 | L40: Proposed Cooling Energy Use (Elec) | N40: kWh/m2 | P40: Proposed Cooling Energy Use (Elec) | R40: kWh/m2 | T40: Proposed Cooling Energy Use (Elec) | V40: kWh/m2
C41: Proposed Heating Energy Use (Gas) | E41: MJ/m2 | H41: Proposed Heating Energy Use (Gas) | J41: MJ/m2 | L41: Proposed Heating Energy Use (Gas) | M41: 450 | N41: MJ/m2 | P41: Proposed Heating Energy Use (Gas) | R41: MJ/m2 | T41: Proposed Heating Energy Use (Gas) | V41: MJ/m2
C42: Proposed Cooling Energy Use (Gas) | E42: MJ/m2 | H42: Proposed Cooling Energy Use (Gas) | J42: MJ/m2 | L42: Proposed Cooling Energy Use (Gas) | M42: 200 | N42: MJ/m2 | P42: Proposed Cooling Energy Use (Gas) | R42: MJ/m2 | T42: Proposed Cooling Energy Use (Gas) | V42: MJ/m2
C43: Proposed Fans | E43: kWh/m2 | H43: Proposed Fans | J43: kWh/m2 | L43: Proposed Fans | N43: kWh/m2 | P43: Proposed Fans | R43: kWh/m2 | T43: Proposed Fans | V43: kWh/m2
C44: Proposed Lighting | E44: kWh/m2 | H44: Proposed Lighting | J44: kWh/m2 | L44: Proposed Lighting | N44: kWh/m2 | P44: Proposed Lighting | R44: kWh/m2 | T44: Proposed Lighting | V44: kWh/m2
C46: Solar PV (whole building) | E46: kWh
B50: Water (BESS)
C52: Retail | H52: Office | L52: Student Accomodation | P52: Educational | T52: Aged Care
C53: Type of hot water system | D53: Heat pump | H53: Type of hot water system | I53: Electric Instantaeous | L53: Type of hot water system | M53: Electric Instantaeous | P53: Type of hot water system | Q53: Electric Instantaeous | T53: Type of hot water system | U53: Electric Instantaeous
C54: Efficiency of hot water system | D54: =VLOOKUP(D53,Table9[#All],2,FALSE) -> 2.5 | E54: COP | H54: Efficiency of hot water system | I54: =VLOOKUP(I53,Table9[#All],2,FALSE) -> 1 | J54: COP | L54: Efficiency of hot water system | M54: =VLOOKUP(M53,Table9[#All],2,FALSE) -> 1 | N54: COP | P54: Efficiency of hot water system | Q54: =VLOOKUP(Q53,Table9[#All],2,FALSE) -> 1 | R54: COP | T54: Efficiency of hot water system | U54: =VLOOKUP(U53,Table9[#All],2,FALSE) -> 1 | V54: COP
C55: Number of occupants | D55: =D6/3 -> 0 | E55: Occupants | H55: Number of occupants | I55: =D7/10 -> 0 | J55: Occupants | L55: Number of occupants | M55: =G8 -> 0 | N55: Occupants | P55: Number of occupants | Q55: =D9/3 -> 0 | R55: Occupants | T55: Number of occupants | U55: =G10*1.1 -> 0 | V55: Occupants
...

Sheet Graphs

Sheet Calculations Retail
B2: Reference | F2: Proposed
B3: Heating and Cooling Demand (Elec) (kWh) | C3: Quantity | D3: Unit | G3: Quantity | H3: Unit
B4: Climate Zone | C4: ='Inputs Non-Residential'!I5 -> 6 | D4: N/A | F4: Climate Zone | G4: ='Inputs Non-Residential'!I5 -> 6 | H4: N/A
B5: Heating & Cooling Load | C5: =VLOOKUP(C4,Table12[#All],2,FALSE) -> 28.223452 | D5: kWh/m2 | F5: Heating & Cooling Load | G5: =VLOOKUP(C4,Table12[#All],2,FALSE)*(1-('Inputs Non-Residential'!D23/100)) -> 27.658983 | H5: kWh/m2
B7: Reference Efficiency HVAC System | C7: 3.1 | D7: COP | F7: Efficiency HVAC System (heating) | G7: ='Inputs Non-Residential'!D25 -> 3.4 | H7: COP
B9: Reference Heating & Cooling Energy Use | C9: =IF(SUM('Inputs Non-Residential'!D32:D37)=0,(C5/C7)*'Inputs Non-Residential'!D6,(('Inputs Non-Residential'!D32+'Inputs Non-Residential'!D33)*'Inputs Non-Residential'!D6)) -> 0 | D9: kWh/yr | F9: Heating & Cooling Energy Use | G9: =IF(SUM('Inputs Non-Residential'!D39:D44)=0,(G5/G7)*'Inputs Non-Residential'!D6,(('Inputs Non-Residential'!D39+'Inputs Non-Residential'!D40)*'Inputs Non-Residential'!D6)) -> 0 | H9: kWh/yr
B11: Heating and Cooling Demand (Gas) (MJ) | C11: Quantity | D11: Unit | G11: Quantity | H11: Unit
B12: Climate Zone | C12: ='Inputs Non-Residential'!I5 -> 6 | D12: N/A | F12: Climate Zone | G12: ='Inputs Non-Residential'!I5 -> 6 | H12: N/A
B13: Heating & Cooling Load | C13: =SUM('Inputs Non-Residential'!D34:D35) -> 0 | D13: MJ/m2 | F13: Heating & Cooling Load | G13: =SUM('Inputs Non-Residential'!D41:D42) -> 0 | H13: MJ/m2
B15: Reference Efficiency HVAC System | C15: 3.1 | D15: COP | F15: Efficiency HVAC System (heating) | G15: ='Inputs Non-Residential'!D25 -> 3.4 | H15: COP
B17: Reference Heating & Cooling Energy Use | C17: =SUM('Inputs Non-Residential'!D34:D35)*'Inputs Non-Residential'!D6 -> 0 | D17: MJ/yr | F17: Heating & Cooling Energy Use | G17: =SUM('Inputs Non-Residential'!D41:D42)*'Inputs Non-Residential'!D6 -> 0 | H17: MJ/yr
B19: Fan Energy (kWh)
B21: Reference Fan Energy | C21: ='Inputs Non-Residential'!D36*'Inputs Non-Residential'!D6 -> 0 | D21: kWh/yr | F21: Proposed Fan Energy | G21: ='Inputs Non-Residential'!D43*'Inputs Non-Residential'!D6 -> 0 | H21: kWh/yr
B23: Lighting (kWh) | C23: Quantity | D23: Unit | G23: Quantity | H23: Unit
B24: Reference Lighting Power Density | C24: 14 | D24: W/m2 | F24: Lighting Power Density | G24: =C24*(1-('Inputs Non-Residential'!D26/100)) -> 14 | H24: W/m2
B25: Hours of Operation per Day | C25: 8 | D25: hours | F25: Hours of Operation per Day | G25: 8 | H25: hours
B27: Reference Lighting Energy Use | C27: =IF('Inputs Non-Residential'!D37=0,((C24/1000)*C25*'Inputs Non-Residential'!D6*365),('Inputs Non-Residential'!D37*'Inputs Non-Residential'!D6)) -> 0 | D27: kWh/yr | F27: Lighting Energy Use | G27: =IF('Inputs Non-Residential'!D44=0,((G24/1000)*G25*'Inputs Non-Residential'!D6*365),'Inputs Non-Residential'!D44*'Inputs Non-Residential'!D6) -> 0 | H27: kWh/yr
B29: Hot Water (kWh) | C29: Quantity | D29: Unit | G29: Quantity | H29: Unit
B30: Reference Total Hot Water Use | C30: =('Inputs Non-Residential'!D55*0.26*20*4.5*365) -> 0 | D30: L/yr | F30: Total Hot Water Use | G30: =C30*(1-('Inputs Non-Residential'!D56/100)) -> 0 | H30: L/yr
B31: Cold Water Temp | C31: 15 | D31: C | F31: Cold Water Temp | G31: 15 | H31: C
B32: Hot Water Temp | C32: 60 | D32: C | F32: Hot Water Temp | G32: 60 | H32: C
B33: Water Heat Capacity | C33: 0.004186 | D33: MJ/L/C | F33: Water Heat Capacity | G33: 0.004186 | H33: MJ/L/C
B34: Reference Energy Required | C34: =(C30*C33*(C32-C31))/3.6 -> 0 | D34: kWh/yr | F34: Energy Required | G34: =(G30*G33*(G32-G31))/3.6 -> 0 | H34: kWh/yr
B36: Reference Hot Water System Efficiency | C36: 1 | D36: COP | F36: Hot Water System Efficiency | G36: ='Inputs Non-Residential'!D54 -> 2.5 | H36: COP
B38: Reference Hot Water Energy Use | C38: =C34/C36 -> 0 | D38: kWh/yr | F38: Hot Water Energy Use | G38: =G34/G36 -> 0 | H38: kWh/yr
B40: Cooktops (kWh) | C40: Quantity | D40: Unit
B41: Type | C41: Gas | F41: Type | G41: ='Inputs Non-Residential'!D27 -> None
B42: Energy Source | C42: Gas | F42: Energy Source | G42: =IF('Inputs Non-Residential'!D27="Gas","Gas","Electric") -> Electric
B43: Energy Use system | C43: ='Drop down'!D19 -> 28.8 | D43: MJ/hr | F43: Energy use system | G43: =VLOOKUP(G41,Table10[#All],3,FALSE) -> 0 | H43: =VLOOKUP(G41,Table10[#All],4,FALSE) -> kW/h
B44: Average hours of use per day | C44: 6 | D44: hours/day | F44: Average hours of use per day | G44: 6 | H44: hours/day
B46: Reference Cooktop Energy Use | C46: =IF('Inputs Non-Residential'!D27="None",0,(C43*C44*365)) -> 0 | D46: =IF(C42="Gas","MJ/yr","kWh/yr") -> MJ/yr | F46: Cooktop Energy Use | G46: =IF(G42="Gas",(G43*G44*365),(G43*G44*365)) -> 0 | H46: =IF(G42="Gas","MJ/yr","kWh/yr") -> kWh/yr

Sheet Calculations Office
B3: Heating and Cooling Demand (Elec) (kWh) | C3: Quantity | D3: Unit | G3: Quantity | H3: Unit
B4: Climate Zone | C4: ='Inputs Non-Residential'!I5 -> 6 | D4: N/A | F4: Climate Zone | G4: ='Inputs Non-Residential'!I5 -> 6 | H4: N/A
B5: Heating & Cooling Load | C5: =VLOOKUP(C4,Table12[#All],3,FALSE) -> 16.7 | D5: kWh/m2 | F5: Heating & Cooling Load | G5: =VLOOKUP(C4,Table12[#All],3,FALSE)*(1-('Inputs Non-Residential'!I23/100)) -> 16.7 | H5: kWh/m2
B7: Reference Efficiency HVAC System | C7: 3.1 | D7: COP | F7: Efficiency HVAC System (heating) | G7: ='Inputs Non-Residential'!I25 -> 3.4 | H7: COP
B9: Reference Heating & Cooling Energy Use | C9: =IF(SUM('Inputs Non-Residential'!I32:I33)=0,(C5*'Inputs Non-Residential'!D7)/C7,(('Inputs Non-Residential'!I32+'Inputs Non-Residential'!I33)*'Inputs Non-Residential'!D7)) -> 0 | D9: kWh/yr | F9: Heating & Cooling Energy Use | G9: =IF(SUM('Inputs Non-Residential'!I39:I40)=0,(G5*'Inputs Non-Residential'!D7)/G7,(('Inputs Non-Residential'!I39+'Inputs Non-Residential'!I40)*'Inputs Non-Residential'!D7)) -> 0 | H9: kWh/yr
B11: Heating and Cooling Demand (Gas) (MJ) | C11: Quantity | D11: Unit | G11: Quantity | H11: Unit
B12: Climate Zone | C12: ='Inputs Non-Residential'!I5 -> 6 | D12: N/A | F12: Climate Zone | G12: ='Inputs Non-Residential'!I5 -> 6 | H12: N/A
B13: Heating & Cooling Load | C13: =SUM('Inputs Non-Residential'!I34:I35) -> 0 | D13: MJ/m2 | F13: Heating & Cooling Load | G13: =SUM('Inputs Non-Residential'!I41:I42) -> 0 | H13: MJ/m2
B15: Reference Efficiency HVAC System | C15: 3.1 | D15: COP | F15: Efficiency HVAC System (heating) | G15: ='Inputs Non-Residential'!I25 -> 3.4 | H15: COP
B17: Reference Heating & Cooling Energy Use | C17: =SUM('Inputs Non-Residential'!I34:I35)*'Inputs Non-Residential'!D7 -> 0 | D17: MJ/yr | F17: Heating & Cooling Energy Use | G17: =SUM('Inputs Non-Residential'!I41:I42)*'Inputs Non-Residential'!D7 -> 0 | H17: MJ/yr
B19: Fan Energy (kWh)
B21: Reference Fan Energy | C21: ='Inputs Non-Residential'!I36*'Inputs Non-Residential'!D7 -> 0 | D21: kWh/yr | F21: Proposed Fan Energy | G21: ='Inputs Non-Residential'!I43*'Inputs Non-Residential'!D7 -> 0 | H21: kWh/yr
B23: Appliances (kWh) | C23: Quantity | D23: Unit | G23: Quantity | H23: Unit
B24: Reference average power density | C24: 11 | D24: W/m2 | F24: Targeted averager power density | G24: 11 | H24: W/m2
B25: Average hours of use per day | C25: 8 | D25: hours | F25: Average hours of use per day | G25: 8 | H25: hours
B27: Reference Appliance Energy Use | C27: =(C24/1000)*(C25+((24-C25)*0.25))*(365-104)*'Inputs Non-Residential'!D7 -> 0 | D27: kWh/yr | F27: Appliance Energy Use | G27: =(G24/1000)*(G25+((24-G25)*0.25))*(365-104)*'Inputs Non-Residential'!D7 -> 0 | H27: kWh/yr
B29: Lighting (kWh) | C29: Quantity | D29: Unit | G29: Quantity | H29: Unit
B30: Reference Lighting Power Density | C30: 4.5 | D30: W/m2 | F30: Lighting Power Density | G30: =C30*(1-('Inputs Non-Residential'!I26/100)) -> 4.5 | H30: W/m2
B31: Hours of Operation per Day | C31: 10 | D31: hours | F31: Hours of Operation per Day (Living) | G31: 10 | H31: hours
B33: Reference Lighting Energy Use | C33: =IF('Inputs Non-Residential'!I37=0,((C30/1000)*C31*'Inputs Non-Residential'!D7*(365-104)),('Inputs Non-Residential'!I37*'Inputs Non-Residential'!D7)) -> 0 | D33: kWh/yr | F33: Lighting Energy Use | G33: =IF('Inputs Non-Residential'!I44=0,((G30/1000)*G31*'Inputs Non-Residential'!D7*(365-104)),('Inputs Non-Residential'!I44*'Inputs Non-Residential'!D7)) -> 0 | H33: kWh/yr
B35: Hot Water (kWh) | C35: Quantity | D35: Unit | G35: Quantity | H35: Unit
B36: Reference Total Hot Water Use | C36: ='Inputs Non-Residential'!I55*4*(365-104) -> 0 | D36: L/yr | F36: Total Hot Water Use | G36: =C36*(1-('Inputs Non-Residential'!I56/100)) -> 0 | H36: L/yr
B37: Cold Water Temp | C37: 15 | D37: C | F37: Cold Water Temp | G37: 15 | H37: C
B38: Hot Water Temp | C38: 60 | D38: C | F38: Hot Water Temp | G38: 60 | H38: C
B39: Water Heat Capacity | C39: 0.004186 | D39: MJ/L/C | F39: Water Heat Capacity | G39: 0.004186 | H39: MJ/L/C
B40: Reference Energy Required | C40: =(C36*C39*(C38-C37))/3.6 -> 0 | D40: kWh/yr | F40: Energy Required | G40: =(G36*G39*(G38-G37))/3.6 -> 0 | H40: kWh/yr
B42: Reference Hot Water System Efficiency | C42: 1 | D42: COP | F42: Hot Water System Efficiency | G42: ='Inputs Non-Residential'!I54 -> 1 | H42: COP
B44: Reference Hot Water Energy Use | C44: =C40/C42 -> 0 | D44: kWh/yr | F44: Hot Water Energy Use | G44: =G40/G42 -> 0 | H44: kWh/yr

Sheet Calculations Student Accom
B3: Heating and Cooling Demand (Elec) (kWh) | C3: Quantity | D3: Unit | G3: Quantity | H3: Unit
B4: Climate Zone | C4: ='Inputs Non-Residential'!I5 -> 6 | D4: N/A | F4: Climate Zone | G4: ='Inputs Non-Residential'!I5 -> 6 | H4: N/A
B5: Heating & Cooling Load | C5: =VLOOKUP(C4,Table12[#All],7,FALSE) -> 33.538978 | D5: kWh/m2 | F5: Heating & Cooling Load | G5: =VLOOKUP(C4,Table12[#All],7,FALSE)*(1-('Inputs Non-Residential'!M23/100)) -> 33.538978 | H5: kWh/m2
B7: Reference Efficiency HVAC System | C7: 3.1 | D7: COP | F7: Efficiency HVAC System (heating) | G7: ='Inputs Non-Residential'!M25 -> 3.4 | H7: COP
B9: Reference Heating & Cooling Energy Use | C9: =IF(SUM('Inputs Non-Residential'!M32:M33)=0,(C5*'Inputs Non-Residential'!D8)/C7,(('Inputs Non-Residential'!M32+'Inputs Non-Residential'!M33)*'Inputs Non-Residential'!D8)) -> 0 | D9: kWh/yr | F9: Heating & Cooling Energy Use | G9: =IF(SUM('Inputs Non-Residential'!M39:M40)=0,(G5*'Inputs Non-Residential'!D8)/G7,(('Inputs Non-Residential'!M39+'Inputs Non-Residential'!M40)*'Inputs Non-Residential'!D8)) -> 0 | H9: kWh/yr
B11: Heating and Cooling Demand (Gas) (MJ) | C11: Quantity | D11: Unit | G11: Quantity | H11: Unit
B12: Climate Zone | C12: ='Inputs Non-Residential'!I5 -> 6 | D12: N/A | F12: Climate Zone | G12: ='Inputs Non-Residential'!I5 -> 6 | H12: N/A
B13: Heating & Cooling Load | C13: =SUM('Inputs Non-Residential'!M34:M35) -> 1750 | D13: MJ/m2 | F13: Heating & Cooling Load | G13: =SUM('Inputs Non-Residential'!M41:M42) -> 650 | H13: MJ/m2
B15: Reference Efficiency HVAC System | C15: 3.1 | D15: COP | F15: Efficiency HVAC System (heating) | G15: ='Inputs Non-Residential'!M25 -> 3.4 | H15: COP
B17: Reference Heating & Cooling Energy Use | C17: =SUM('Inputs Non-Residential'!M34:M35)*'Inputs Non-Residential'!D8 -> 0 | D17: MJ/yr | F17: Heating & Cooling Energy Use | G17: =SUM('Inputs Non-Residential'!M41:M42)*'Inputs Non-Residential'!D8 -> 0 | H17: MJ/yr
B19: Fan Energy (kWh)
B21: Reference Fan Energy | C21: ='Inputs Non-Residential'!M36*'Inputs Non-Residential'!D8 -> 0 | D21: kWh/yr | F21: Proposed Fan Energy | G21: ='Inputs Non-Residential'!M43*'Inputs Non-Residential'!D8 -> 0 | H21: kWh/yr
B23: Appliances (kWh) | C23: Quantity | D23: Unit | G23: Quantity | H23: Unit
B24: Reference average power density | C24: 5 | D24: W/m2 | F24: Targeted averager power density | G24: 5 | H24: W/m2
B25: Average hours of use per day | C25: 8 | D25: hours | F25: Average hours of use per day | G25: 8 | H25: hours
B27: Reference Appliance Energy Use | C27: =(C24/1000)*C25*'Inputs Non-Residential'!D8*365 -> 0 | D27: kWh/yr | F27: Appliance Energy Use | G27: =(G24/1000)*G25*'Inputs Non-Residential'!D8*365 -> 0 | H27: kWh/yr
B29: Lighting (kWh) | C29: Quantity | D29: Unit | G29: Quantity | H29: Unit
B30: Reference Lighting Power Density | C30: 4.5 | D30: W/m2 | F30: Lighting Power Density | G30: =C30*(1-('Inputs Non-Residential'!M26/100)) -> 4.5 | H30: W/m2
B31: Hours of Operation per Day | C31: 10 | D31: hours | F31: Hours of Operation per Day (Living) | G31: 10 | H31: hours
B33: Reference Lighting Energy Use | C33: =IF('Inputs Non-Residential'!M37=0,((C30/1000)*C31*'Inputs Non-Residential'!D8*365),('Inputs Non-Residential'!M37*'Inputs Non-Residential'!D8)) -> 0 | D33: kWh/yr | F33: Lighting Energy Use | G33: =IF('Inputs Non-Residential'!M44=0,((G30/1000)*G31*'Inputs Non-Residential'!D8*365),('Inputs Non-Residential'!M44*'Inputs Non-Residential'!D8)) -> 0 | H33: kWh/yr
B35: Hot Water (kWh) | C35: Quantity | D35: Unit | G35: Quantity | H35: Unit
B36: Reference Total Hot Water Use | C36: ='Inputs Non-Residential'!M55*60*365 -> 0 | D36: L/yr | F36: Total Hot Water Use | G36: =C36*(1-('Inputs Non-Residential'!M56/100)) -> 0 | H36: L/yr
B37: Cold Water Temp | C37: 15 | D37: C | F37: Cold Water Temp | G37: 15 | H37: C
B38: Hot Water Temp | C38: 60 | D38: C | F38: Hot Water Temp | G38: 60 | H38: C
B39: Water Heat Capacity | C39: 0.004186 | D39: MJ/L/C | F39: Water Heat Capacity | G39: 0.004186 | H39: MJ/L/C
B40: Reference Energy Required | C40: =(C36*C39*(C38-C37))/3.6 -> 0 | D40: kWh/yr | F40: Energy Required | G40: =(G36*G39*(G38-G37))/3.6 -> 0 | H40: kWh/yr
B42: Reference Hot Water System Efficiency | C42: 1 | D42: COP | F42: Hot Water System Efficiency | G42: ='Inputs Non-Residential'!M54 -> 1 | H42: COP
B44: Reference Hot Water Energy Use | C44: =C40/C42 -> 0 | D44: kWh/yr | F44: Hot Water Energy Use | G44: =G40/G42 -> 0 | H44: kWh/yr
B46: Cooktops (kWh) | C46: Quantity | D46: Unit | F46: Cooktops (kWh) | G46: Quantity | H46: Unit
B47: Type | C47: Gas | F47: Type | G47: ='Inputs Non-Residential'!M27 -> None
B48: Energy source | C48: Gas | F48: Energy source | G48: =IF('Inputs Non-Residential'!M27="Gas","Gas","Electric") -> Electric
B49: Energy Use system | C49: ='Drop down'!C19 -> 6 | D49: MJ/hr | F49: Energy Use system | G49: =VLOOKUP(G47,Table10[#All],3,FALSE) -> 0 | H49: =VLOOKUP(G47,Table10[#All],4,FALSE) -> kW/h
B50: Average hours of use per day | C50: 1.5 | D50: hours/day | F50: Average hours of use per day | G50: 1.5 | H50: hours/day
B52: Reference Cooktop Energy Use | C52: =IF('Inputs Non-Residential'!M27="None",0,(C49*C50*365*'Inputs Non-Residential'!G8)) -> 0 | D52: MJ/yr | F52: Reference Cooktop Energy Use | G52: =G49*G50*365*'Inputs Non-Residential'!G8 -> 0 | H52: kWh/yr

Sheet Calculations Educational
B3: Heating and Cooling Demand (Elec) (kWh) | C3: Quantity | D3: Unit | G3: Quantity | H3: Unit
B4: Climate Zone | C4: ='Inputs Non-Residential'!I5 -> 6 | D4: N/A | F4: Climate Zone | G4: ='Inputs Non-Residential'!I5 -> 6 | H4: N/A
B5: Heating & Cooling Load | C5: =VLOOKUP(C4,Table12[#All],6,FALSE) -> 11.504649 | D5: kWh/m2 | F5: Heating & Cooling Load | G5: =VLOOKUP(C4,Table12[#All],6,FALSE)*(1-('Inputs Non-Residential'!Q23/100)) -> 11.504649 | H5: kWh/m2
B7: Reference Efficiency HVAC System | C7: 3.1 | D7: COP | F7: Efficiency HVAC System (heating) | G7: ='Inputs Non-Residential'!Q25 -> 3.4 | H7: COP
B9: Reference Heating & Cooling Energy Use | C9: =IF(SUM('Inputs Non-Residential'!Q32:Q33)=0,(C5*'Inputs Non-Residential'!D9)/C7,(('Inputs Non-Residential'!Q32+'Inputs Non-Residential'!Q33)*'Inputs Non-Residential'!D9)) -> 0 | D9: kWh/yr | F9: Heating & Cooling Energy Use | G9: =IF(SUM('Inputs Non-Residential'!Q39:Q40)=0,(G5*'Inputs Non-Residential'!D9)/G7,(('Inputs Non-Residential'!Q39+'Inputs Non-Residential'!Q40)*'Inputs Non-Residential'!D9)) -> 0 | H9: kWh/yr
B11: Heating and Cooling Demand (Gas) (MJ) | C11: Quantity | D11: Unit | G11: Quantity | H11: Unit
B12: Climate Zone | C12: ='Inputs Non-Residential'!I5 -> 6 | D12: N/A | F12: Climate Zone | G12: ='Inputs Non-Residential'!I5 -> 6 | H12: N/A
B13: Heating & Cooling Load | C13: =SUM('Inputs Non-Residential'!Q34:Q35) -> 0 | D13: MJ/m2 | F13: Heating & Cooling Load | G13: =SUM('Inputs Non-Residential'!Q41:Q42) -> 0 | H13: MJ/m2
B15: Reference Efficiency HVAC System | C15: 3.1 | D15: COP | F15: Efficiency HVAC System (heating) | G15: ='Inputs Non-Residential'!Q25 -> 3.4 | H15: COP
B17: Reference Heating & Cooling Energy Use | C17: =SUM('Inputs Non-Residential'!Q34:Q35)*'Inputs Non-Residential'!D9 -> 0 | D17: MJ/yr | F17: Heating & Cooling Energy Use | G17: =SUM('Inputs Non-Residential'!Q41:Q42)*'Inputs Non-Residential'!D9 -> 0 | H17: MJ/yr
B19: Fan Energy (kWh)
B21: Reference Fan Energy | C21: ='Inputs Non-Residential'!Q36*'Inputs Non-Residential'!D9 -> 0 | D21: kWh/yr | F21: Proposed Fan Energy | G21: ='Inputs Non-Residential'!Q43*'Inputs Non-Residential'!D9 -> 0 | H21: kWh/yr
B23: Appliances (kWh) | C23: Quantity | D23: Unit | G23: Quantity | H23: Unit
B24: Reference average power density | C24: 11 | D24: W/m2 | F24: Targeted averager power density | G24: 11 | H24: W/m2
B25: Average hours of use per day | C25: 8 | D25: hours | F25: Average hours of use per day | G25: 8 | H25: hours
B27: Reference Appliance Energy Use | C27: =(C24/1000)*(C25+((24-C25)*0.25))*(365-104)*'Inputs Non-Residential'!D9 -> 0 | D27: kWh/yr | F27: Appliance Energy Use | G27: =(G24/1000)*(G25+((24-G25)*0.25))*(365-104)*'Inputs Non-Residential'!D9 -> 0 | H27: kWh/yr
B29: Lighting (kWh) | C29: Quantity | D29: Unit | G29: Quantity | H29: Unit
B30: Reference Lighting Power Density | C30: 4.5 | D30: W/m2 | F30: Lighting Power Density | G30: =C30*(1-('Inputs Non-Residential'!Q26/100)) -> 4.5 | H30: W/m2
B31: Hours of Operation per Day | C31: 10 | D31: hours | F31: Hours of Operation per Day (Living) | G31: 10 | H31: hours
B33: Reference Lighting Energy Use | C33: =IF('Inputs Non-Residential'!Q37=0,((C30/1000)*C31*'Inputs Non-Residential'!D9*(365-104)),('Inputs Non-Residential'!Q37*'Inputs Non-Residential'!D9)) -> 0 | D33: kWh/yr | F33: Lighting Energy Use | G33: =IF('Inputs Non-Residential'!Q44=0,((G30/1000)*G31*'Inputs Non-Residential'!D9*(365-104)),('Inputs Non-Residential'!Q44*'Inputs Non-Residential'!D9)) -> 0 | H33: kWh/yr
B35: Hot Water (kWh) | C35: Quantity | D35: Unit | G35: Quantity | H35: Unit
B36: Reference Total Hot Water Use | C36: ='Inputs Non-Residential'!Q55*4*(365-104) -> 0 | D36: L/yr | F36: Total Hot Water Use | G36: =C36*(1-('Inputs Non-Residential'!Q56/100)) -> 0 | H36: L/yr
B37: Cold Water Temp | C37: 15 | D37: C | F37: Cold Water Temp | G37: 15 | H37: C
B38: Hot Water Temp | C38: 60 | D38: C | F38: Hot Water Temp | G38: 60 | H38: C
B39: Water Heat Capacity | C39: 0.004186 | D39: MJ/L/C | F39: Water Heat Capacity | G39: 0.004186 | H39: MJ/L/C
B40: Reference Energy Required | C40: =(C36*C39*(C38-C37))/3.6 -> 0 | D40: kWh/yr | F40: Energy Required | G40: =(G36*G39*(G38-G37))/3.6 -> 0 | H40: kWh/yr
B42: Reference Hot Water System Efficiency | C42: 1 | D42: COP | F42: Hot Water System Efficiency | G42: ='Inputs Non-Residential'!Q54 -> 1 | H42: COP
B44: Reference Hot Water Energy Use | C44: =C40/C42 -> 0 | D44: kWh/yr | F44: Hot Water Energy Use | G44: =G40/G42 -> 0 | H44: kWh/yr

Sheet Calculations Aged Care
B3: Heating and Cooling Demand (Elec) (kWh) | C3: Quantity | D3: Unit | G3: Quantity | H3: Unit
B4: Climate Zone | C4: ='Inputs Non-Residential'!I5 -> 6 | D4: N/A | F4: Climate Zone | G4: ='Inputs Non-Residential'!I5 -> 6 | H4: N/A
B5: Heating & Cooling Load | C5: =VLOOKUP(C4,Table12[#All],5,FALSE) -> 28.316456 | D5: kWh/m2 | F5: Heating & Cooling Load | G5: =VLOOKUP(C4,Table12[#All],5,FALSE)*(1-('Inputs Non-Residential'!M23/100)) -> 28.316456 | H5: kWh/m2
B7: Reference Efficiency HVAC System | C7: 3.1 | D7: COP | F7: Efficiency HVAC System (heating) | G7: ='Inputs Non-Residential'!U25 -> 3.4 | H7: COP
B9: Reference Heating & Cooling Energy Use | C9: =IF(SUM('Inputs Non-Residential'!U32:U33)=0,(C5*'Inputs Non-Residential'!D10)/C7,(('Inputs Non-Residential'!U32+'Inputs Non-Residential'!U33)*'Inputs Non-Residential'!D10)) -> 0 | D9: kWh/yr | F9: Heating & Cooling Energy Use | G9: =IF(SUM('Inputs Non-Residential'!U39:U40)=0,(G5*'Inputs Non-Residential'!D10)/G7,(('Inputs Non-Residential'!U39+'Inputs Non-Residential'!U40)*'Inputs Non-Residential'!D10)) -> 0 | H9: kWh/yr
B11: Heating and Cooling Demand (Gas) (MJ) | C11: Quantity | D11: Unit | G11: Quantity | H11: Unit
B12: Climate Zone | C12: ='Inputs Non-Residential'!I5 -> 6 | D12: N/A | F12: Climate Zone | G12: ='Inputs Non-Residential'!I5 -> 6 | H12: N/A
B13: Heating & Cooling Load | C13: =SUM('Inputs Non-Residential'!U34:U35) -> 0 | D13: MJ/m2 | F13: Heating & Cooling Load | G13: =SUM('Inputs Non-Residential'!U41:U42) -> 0 | H13: MJ/m2
B15: Reference Efficiency HVAC System | C15: 3.1 | D15: COP | F15: Efficiency HVAC System (heating) | G15: ='Inputs Non-Residential'!U25 -> 3.4 | H15: COP
B17: Reference Heating & Cooling Energy Use | C17: =SUM('Inputs Non-Residential'!U34:U35)*'Inputs Non-Residential'!D10 -> 0 | D17: MJ/yr | F17: Heating & Cooling Energy Use | G17: =SUM('Inputs Non-Residential'!U41:U42)*'Inputs Non-Residential'!D10 -> 0 | H17: MJ/yr
B19: Fan Energy (kWh)
B21: Reference Fan Energy | C21: ='Inputs Non-Residential'!U36*'Inputs Non-Residential'!D10 -> 0 | D21: kWh/yr | F21: Proposed Fan Energy | G21: ='Inputs Non-Residential'!U43*'Inputs Non-Residential'!D10 -> 0 | H21: kWh/yr
B23: Appliances (kWh) | C23: Quantity | D23: Unit | G23: Quantity | H23: Unit
B24: Reference average power density | C24: 5 | D24: W/m2 | F24: Targeted averager power density | G24: 5 | H24: W/m2
B25: Average hours of use per day | C25: 8 | D25: hours | F25: Average hours of use per day | G25: 8 | H25: hours
B27: Reference Appliance Energy Use | C27: =(C24/1000)*C25*'Inputs Non-Residential'!D10*365 -> 0 | D27: kWh/yr | F27: Appliance Energy Use | G27: =(G24/1000)*G25*'Inputs Non-Residential'!D10*365 -> 0 | H27: kWh/yr
B29: Lighting (kWh) | C29: Quantity | D29: Unit | G29: Quantity | H29: Unit
B30: Reference Lighting Power Density | C30: 4.75 | D30: W/m2 | F30: Lighting Power Density | G30: =C30*(1-('Inputs Non-Residential'!U26/100)) -> 4.75 | H30: W/m2
B31: Hours of Operation per Day | C31: 10 | D31: hours | F31: Hours of Operation per Day (Living) | G31: 10 | H31: hours
B33: Reference Lighting Energy Use | C33: =IF('Inputs Non-Residential'!U37=0,((C30/1000)*C31*'Inputs Non-Residential'!D10*365),('Inputs Non-Residential'!U37*'Inputs Non-Residential'!D10)) -> 0 | D33: kWh/yr | F33: Lighting Energy Use | G33: =IF('Inputs Non-Residential'!U44=0,((G30/1000)*G31*'Inputs Non-Residential'!D10*365),('Inputs Non-Residential'!U44*'Inputs Non-Residential'!D10)) -> 0 | H33: kWh/yr
B35: Hot Water (kWh) | C35: Quantity | D35: Unit | G35: Quantity | H35: Unit
B36: Reference Total Hot Water Use | C36: ='Inputs Non-Residential'!U55*60*365 -> 0 | D36: L/yr | F36: Total Hot Water Use | G36: =C36*(1-('Inputs Non-Residential'!U56/100)) -> 0 | H36: L/yr
B37: Cold Water Temp | C37: 15 | D37: C | F37: Cold Water Temp | G37: 15 | H37: C
B38: Hot Water Temp | C38: 60 | D38: C | F38: Hot Water Temp | G38: 60 | H38: C
B39: Water Heat Capacity | C39: 0.004186 | D39: MJ/L/C | F39: Water Heat Capacity | G39: 0.004186 | H39: MJ/L/C
B40: Reference Energy Required | C40: =(C36*C39*(C38-C37))/3.6 -> 0 | D40: kWh/yr | F40: Energy Required | G40: =(G36*G39*(G38-G37))/3.6 -> 0 | H40: kWh/yr
B42: Reference Hot Water System Efficiency | C42: 1 | D42: COP | F42: Hot Water System Efficiency | G42: ='Inputs Non-Residential'!U54 -> 1 | H42: COP
B44: Reference Hot Water Energy Use | C44: =C40/C42 -> 0 | D44: kWh/yr | F44: Hot Water Energy Use | G44: =G40/G42 -> 0 | H44: kWh/yr
B46: Cooktops (kWh) | C46: Quantity | D46: Unit | F46: Cooktops (kWh) | G46: Quantity | H46: Unit
B47: Type | C47: Gas | F47: Type | G47: ='Inputs Non-Residential'!U27 -> None
B48: Energy source | C48: Gas | F48: Energy source | G48: =IF('Inputs Non-Residential'!U27="Gas","Gas","Electric") -> Electric
B49: Energy Use system | C49: ='Drop down'!D19 -> 28.8 | D49: MJ/hr | F49: Energy Use system | G49: =VLOOKUP(G47,Table10[#All],3,FALSE) -> 0 | H49: =VLOOKUP(G47,Table10[#All],4,FALSE) -> kW/h
B50: Average hours of use per day | C50: 6 | D50: hours/day | F50: Average hours of use per day | G50: 6 | H50: hours/day
B52: Reference Cooktop Energy Use | C52: =IF('Inputs Non-Residential'!U27="None",0,(C49*C50*365)) -> 0 | D52: MJ/yr | F52: Reference Cooktop Energy Use | G52: =G49*G50*365 -> 0 | H52: kWh/yr

Sheet Calculations C&S
B2: Carpark Ventilation (kWh) | C2: Quantity | D2: Unit | G2: Quantity | H2: Unit
B4: Reference Ventilation | C4: ='Inputs Non-Residential'!D11*42.33*(3212/8760) -> 0 | D4: kWh/yr | F4: Heating & Cooling Energy Use | G4: ='Inputs Non-Residential'!D11*42.33*(3212/8760) -> 0 | H4: kWh/yr
B6: Lighting Carpark (kWh) | C6: Quantity | D6: Unit | G6: Quantity | H6: Unit
B7: Reference Lighting Power Density | C7: 2 | D7: W/m2 | F7: Lighting Power Density | G7: 2 | H7: W/m2
B8: Hours of Operation per Day | C8: 10 | D8: hours | F8: Hours of Operation per Day (Living) | G8: 10 | H8: hours
B10: Reference Lighting Energy Use | C10: =(C7/1000)*C8*365*'Inputs Non-Residential'!D11 -> 0 | D10: kWh/yr | F10: Lighting Energy Use | G10: =(G7/1000)*G8*365*'Inputs Non-Residential'!D11 -> 0 | H10: kWh/yr
B12: Lighting Services (kWh) | C12: Quantity | D12: Unit | G12: Quantity | H12: Unit
B13: Reference Lighting Power Density | C13: 1.5 | D13: W/m2 | F13: Lighting Power Density | G13: 1.5 | H13: W/m2
B14: Hours of Operation per Day | C14: 4 | D14: hours | F14: Hours of Operation per Day (Living) | G14: 4 | H14: hours
B16: Reference Lighting Energy Use | C16: =(C13/1000)*C14*365*'Inputs Non-Residential'!D12 -> 0 | D16: kWh/yr | F16: Lighting Energy Use | G16: =(G13/1000)*G14*365*'Inputs Non-Residential'!D12 -> 0 | H16: kWh/yr
B18: Lifts (kWh) | C18: Quantity | D18: Unit
B19: Reference Lift Height | C19: ='Inputs Non-Residential'!D14 -> 0 | D19: m | F19: Lift Height | G19: ='Inputs Non-Residential'!D14 -> 0 | H19: m
B20: No. of Lifts | C20: ='Inputs Non-Residential'!D13 -> 0 | F20: No. of Lifts | G20: ='Inputs Non-Residential'!D13 -> 0
B22: Reference Lift Energy Use | C22: =(((110000*((C19/2)/1)*10)/3600)+0.07*24*365)*C20 -> 0 | D22: kWh/yr | G22: =(((110000*((G19/2)/1)*10)/3600)+0.07*24*365)*G20 -> 0 | H22: kWh/yr

Sheet Totals Non-Residential
H2: GHG Emission Factor Elec 2024 | J2: 0.86 | K2: Kg CO2/kWh | R2: Elec Price (normal) | T2: 0.289 | U2: $/kWh | W2: Gas Price | Y2: 0.035 | Z2: $/MJ
H3: GHG Emission Factor Gas | J3: 0.05153 | K3: Kg CO2/MJ | R3: Elec Price (GP) | T3: =T2+0.05 -> 0.339 | U3: $/kWh
H4: GP GHG emissions | J4: 0 | K4: Kg CO2/kWh
C7: Retail
C8: Energy Use (kWh/yr) | E8: Min. BCA 2022 Compliance | F8: ='Inputs Non-Residential'!D5 -> 0 | H8: GHG Emissions (eqtCO2) | J8: Min. BCA 2022 Compliance | K8: ='Inputs Non-Residential'!D5 -> 0 | M8: GHG Emissions (eqtCO2) With GP | O8: Min. BCA 2022 Compliance | P8: ='Inputs Non-Residential'!D5 -> 0 | R8: Energy Cost | T8: Min. BCA 2022 Compliance | U8: ='Inputs Non-Residential'!D5 -> 0
C9: Heating & Cooling (Elec) | E9: ='Calculations Retail'!C9 -> 0 | F9: ='Calculations Retail'!G9 -> 0 | H9: =C9 -> Heating & Cooling (Elec) | J9: =(E9*$J$2)/1000 -> 0 | K9: =(F9*$J$2)/1000 -> 0 | M9: =H9 -> Heating & Cooling (Elec) | O9: =(E9*$J$2)/1000 -> 0 | P9: =IF('Inputs Non-Residential'!D16="Whole Development",((F9*$J$4)/1000),((F9*$J$2)/1000)) -> 0 | R9: =C9 -> Heating & Cooling (Elec) | T9: =E9*$T$2 -> 0 | U9: =F9*$T$2 -> 0
C10: Heating & Cooling (Gas) | E10: ='Calculations Retail'!C17*0.277776 -> 0 | F10: ='Calculations Retail'!G17*0.2777776 -> 0 | H10: Heating & Cooling (Gas) | J10: =('Calculations Retail'!C17*J3)/1000 -> 0 | K10: =('Calculations Retail'!G17*J3)/1000 -> 0 | M10: Heating & Cooling (Gas) | O10: =J10 -> 0 | P10: =K10 -> 0 | R10: Heating & Cooling (Gas) | T10: ='Calculations Retail'!K17*$Y$2 -> 0 | U10: ='Calculations Retail'!O17*$Y$2 -> 0
C11: Fans | E11: ='Calculations Retail'!C21 -> 0 | F11: ='Calculations Retail'!G21 -> 0 | H11: Fans | J11: =(E11*$J$2)/1000 -> 0 | K11: =(F11*$J$2)/1000 -> 0 | M11: Fans | O11: =(E11*$J$2)/1000 -> 0 | P11: =IF('Inputs Non-Residential'!D16="Whole Development",((F11*$J$4)/1000),((F11*$J$2)/1000)) -> 0 | R11: Fans | T11: =E11*$T$2 -> 0 | U11: =F11*$T$2 -> 0
C12: Lighting | E12: ='Calculations Retail'!C27 -> 0 | F12: ='Calculations Retail'!G27 -> 0 | H12: =C12 -> Lighting | J12: =(E12*$J$2)/1000 -> 0 | K12: =(F12*$J$2)/1000 -> 0 | M12: =H12 -> Lighting | O12: =(E12*$J$2)/1000 -> 0 | P12: =IF('Inputs Non-Residential'!D16="Whole Development",((F12*$J$4)/1000),((F12*$J$2)/1000)) -> 0 | R12: =C12 -> Lighting | T12: =E12*$T$2 -> 0 | U12: =F12*$T$2 -> 0
C13: Hot Water | E13: ='Calculations Retail'!C38 -> 0 | F13: ='Calculations Retail'!G38 -> 0 | H13: =C13 -> Hot Water | J13: =(E13*$J$2)/1000 -> 0 | K13: =(F13*$J$2)/1000 -> 0 | M13: =H13 -> Hot Water | O13: =(E13*$J$2)/1000 -> 0 | P13: =IF('Inputs Non-Residential'!D16="Whole Development",((F13*$J$4)/1000),((F13*$J$2)/1000)) -> 0 | R13: =C13 -> Hot Water | T13: =E13*$T$2 -> 0 | U13: =F13*$T$2 -> 0
C14: Cooktops | E14: ='Calculations Retail'!C46*0.277776 -> 0 | F14: =IF('Calculations Retail'!G42="Gas",'Calculations Retail'!G46*0.277776,'Calculations Retail'!G46) -> 0 | H14: =C14 -> Cooktops | J14: =(E14*$J$3*3.6)/1000 -> 0 | K14: =IF('Calculations Retail'!G42="Gas",((F14*$J$3*3.6)/1000),((F14*$J$2)/1000)) -> 0 | M14: =H14 -> Cooktops | O14: =J14 -> 0 | P14: =IF('Calculations Retail'!G42="Gas",(('Totals Non-Residential'!F14*3.6*'Totals Non-Residential'!J3)/1000),IF('Inputs Non-Residential'!D16="Whole Development",((F14*$J$4)/1000),((F14*$J$2)/1000))) -> 0 | R14: =C14 -> Cooktops | T14: =E14*3.6*$Y$2 -> 0 | U14: =IF('Calculations Retail'!G42="Gas",'Totals Non-Residential'!F14*3.6*'Totals Non-Residential'!Y2,'Totals Non-Residential'!F14*$T$2) -> 0
C15: Total | E15: =SUM(E9:E14) -> 0 | F15: =SUM(F9:F14) -> 0 | H15: =C15 -> Total | J15: =SUM(J9:J14) -> 0 | K15: =SUM(K9:K14) -> 0 | M15: =H15 -> Total | O15: =SUM(O9:O14) -> 0 | P15: =SUM(P9:P14) -> 0 | R15: =C15 -> Total | T15: =E15*$T$2 -> 0 | U15: =F15*$T$2 -> 0
C17: Office
C18: Energy Use (kWh/yr) | E18: Min. BCA 2022 Compliance | F18: ='Inputs Non-Residential'!D5 -> 0 | H18: GHG Emissions (eqtCO2) | J18: Min. BCA 2022 Compliance | K18: ='Inputs Non-Residential'!D5 -> 0 | M18: GHG Emissions (eqtCO2) With GP | O18: Min. BCA 2022 Compliance | P18: ='Inputs Non-Residential'!D5 -> 0 | R18: Energy Cost | T18: Min. BCA 2022 Compliance | U18: ='Inputs Non-Residential'!D5 -> 0
C19: Heating & Cooling (Elec) | E19: ='Calculations Office'!C9 -> 0 | F19: ='Calculations Office'!G9 -> 0 | H19: =C19 -> Heating & Cooling (Elec) | J19: =(E19*$J$2)/1000 -> 0 | K19: =(F19*$J$2)/1000 -> 0 | M19: =H19 -> Heating & Cooling (Elec) | O19: =(E19*$J$2)/1000 -> 0 | P19: =IF('Inputs Non-Residential'!D16="Whole Development",((F19*$J$4)/1000),((F19*$J$2)/1000)) -> 0 | R19: =C19 -> Heating & Cooling (Elec) | T19: =E19*$T$2 -> 0 | U19: =F19*$T$2 -> 0
C20: Heating & Cooling (Gas) | E20: ='Calculations Office'!C17*0.277776 -> 0 | F20: ='Calculations Office'!G17*0.277776 -> 0 | H20: =C20 -> Heating & Cooling (Gas) | J20: =('Calculations Office'!G17*J3)/1000 -> 0 | K20: =('Calculations Office'!G17*J3)/1000 -> 0 | M20: =H20 -> Heating & Cooling (Gas) | O20: =J20 -> 0 | P20: =K20 -> 0 | R20: =C20 -> Heating & Cooling (Gas) | T20: ='Calculations Office'!K17*Y2 -> 0 | U20: ='Calculations Office'!O17*Y2 -> 0
C21: Fans | E21: ='Calculations Office'!C21 -> 0 | F21: ='Calculations Office'!G21 -> 0 | H21: Fans | J21: =(E21*$J$2)/1000 -> 0 | K21: =(F21*$J$2)/1000 -> 0 | M21: Fans | O21: =(E21*$J$2)/1000 -> 0 | P21: =IF('Inputs Non-Residential'!D16="Whole Development",((F21*$J$4)/1000),((F21*$J$2)/1000)) -> 0 | R21: Fans | T21: =E21*$T$2 -> 0 | U21: =F21*$T$2 -> 0
C22: Appliances | E22: ='Calculations Office'!C27 -> 0 | F22: ='Calculations Office'!G27 -> 0 | H22: =C22 -> Appliances | J22: =(E22*$J$2)/1000 -> 0 | K22: =(F22*$J$2)/1000 -> 0 | M22: =H22 -> Appliances | O22: =(E22*$J$2)/1000 -> 0 | P22: =IF('Inputs Non-Residential'!D16="Whole Development",((F22*$J$4)/1000),((F22*$J$2)/1000)) -> 0 | R22: =C22 -> Appliances | T22: =E22*$T$2 -> 0 | U22: =F22*$T$2 -> 0
C23: Lighting | E23: ='Calculations Office'!C33 -> 0 | F23: ='Calculations Office'!G33 -> 0 | H23: =C23 -> Lighting | J23: =(E23*$J$2)/1000 -> 0 | K23: =(F23*$J$2)/1000 -> 0 | M23: =H23 -> Lighting | O23: =(E23*$J$2)/1000 -> 0 | P23: =IF('Inputs Non-Residential'!D16="Whole Development",((F23*$J$4)/1000),((F23*$J$2)/1000)) -> 0 | R23: =C23 -> Lighting | T23: =E23*$T$2 -> 0 | U23: =F23*$T$2 -> 0
C24: Hot Water | E24: ='Calculations Office'!C44 -> 0 | F24: ='Calculations Office'!G44 -> 0 | H24: =C24 -> Hot Water | J24: =(E24*$J$2)/1000 -> 0 | K24: =(F24*$J$2)/1000 -> 0 | M24: =H24 -> Hot Water | O24: =(E24*$J$2)/1000 -> 0 | P24: =IF('Inputs Non-Residential'!D16="Whole Development",((F24*$J$4)/1000),((F24*$J$2)/1000)) -> 0 | R24: =C24 -> Hot Water | T24: =E24*$T$2 -> 0 | U24: =F24*$T$2 -> 0
C25: Total | E25: =SUM(E19:E24) -> 0 | F25: =SUM(F19:F24) -> 0 | H25: =C25 -> Total | J25: =SUM(J19:J24) -> 0 | K25: =SUM(K19:K24) -> 0 | M25: =H25 -> Total | O25: =SUM(O19:O24) -> 0 | P25: =SUM(P19:P24) -> 0 | R25: =C25 -> Total | T25: =E25 -> 0 | U25: =F25 -> 0
C27: Student Accomodation
C28: Energy Use (kWh/yr) | E28: Min. BCA 2022 Compliance | F28: ='Inputs Non-Residential'!D5 -> 0 | H28: GHG Emissions (eqtCO2) | J28: Min. BCA 2022 Compliance | K28: ='Inputs Non-Residential'!D5 -> 0 | M28: GHG Emissions (eqtCO2) With GP | O28: Min. BCA 2022 Compliance | P28: ='Inputs Non-Residential'!D5 -> 0 | R28: Energy Cost | T28: Min. BCA 2022 Compliance | U28: ='Inputs Non-Residential'!D5 -> 0
C29: Heating & Cooling (Elec) | E29: ='Calculations Student Accom'!C9 -> 0 | F29: ='Calculations Student Accom'!G9 -> 0 | H29: =C29 -> Heating & Cooling (Elec) | J29: =(E29*$J$2)/1000 -> 0 | K29: =(F29*$J$2)/1000 -> 0 | M29: =H29 -> Heating & Cooling (Elec) | O29: =(E29*$J$2)/1000 -> 0 | P29: =IF('Inputs Non-Residential'!$D$16="Whole Development",((F29*$J$4)/1000),((F29*$J$2)/1000)) -> 0 | R29: =C29 -> Heating & Cooling (Elec) | T29: =E29*$T$2 -> 0 | U29: =F29*$T$2 -> 0
C30: Heating & Cooling (Gas) | E30: ='Calculations Student Accom'!C17*0.277776 -> 0 | F30: ='Calculations Student Accom'!G17*0.277776 -> 0 | H30: Heating & Cooling (Gas) | J30: =('Calculations Student Accom'!C17*J3)/1000 -> 0 | K30: =('Calculations Student Accom'!G17*J3)/1000 -> 0 | M30: Heating & Cooling (Gas) | O30: =J30 -> 0 | P30: =K30 -> 0 | R30: Heating & Cooling (Gas) | T30: ='Calculations Student Accom'!C17*$Y$2 -> 0 | U30: ='Calculations Student Accom'!G17*$Y$2 -> 0
C31: Fans | E31: ='Calculations Student Accom'!C21 -> 0 | F31: ='Calculations Student Accom'!G21 -> 0 | H31: Fans | J31: =(E31*$J$2)/1000 -> 0 | K31: =(F31*$J$2)/1000 -> 0 | M31: Fans | O31: =(E31*$J$2)/1000 -> 0 | P31: =IF('Inputs Non-Residential'!$D$16="Whole Development",((F31*$J$4)/1000),((F31*$J$2)/1000)) -> 0 | R31: Fans | T31: =E31*$T$2 -> 0 | U31: =F31*$T$2 -> 0
C32: Appliances | E32: ='Calculations Student Accom'!C27 -> 0 | F32: ='Calculations Student Accom'!G27 -> 0 | H32: Appliances | J32: =(E32*$J$2)/1000 -> 0 | K32: =(F32*$J$2)/1000 -> 0 | M32: Appliances | P32: =IF('Inputs Non-Residential'!$D$16="Whole Development",((F32*$J$4)/1000),((F32*$J$2)/1000)) -> 0 | R32: Appliances | T32: =E32*$T$2 -> 0 | U32: =F32*$T$2 -> 0
C33: Lighting | E33: ='Calculations Student Accom'!C33 -> 0 | F33: ='Calculations Student Accom'!G33 -> 0 | H33: =C33 -> Lighting | J33: =(E33*$J$2)/1000 -> 0 | K33: =(F33*$J$2)/1000 -> 0 | M33: =H33 -> Lighting | O33: =(E33*$J$2)/1000 -> 0 | P33: =IF('Inputs Non-Residential'!$D$16="Whole Development",((F33*$J$4)/1000),((F33*$J$2)/1000)) -> 0 | R33: =C33 -> Lighting | T33: =E33*$T$2 -> 0 | U33: =F33*$T$2 -> 0
C34: Hot Water | E34: ='Calculations Student Accom'!C44 -> 0 | F34: ='Calculations Student Accom'!G44 -> 0 | H34: =C34 -> Hot Water | J34: =(E34*$J$2)/1000 -> 0 | K34: =(F34*$J$2)/1000 -> 0 | M34: =H34 -> Hot Water | O34: =(E34*$J$2)/1000 -> 0 | P34: =IF('Inputs Non-Residential'!$D$16="Whole Development",((F34*$J$4)/1000),((F34*$J$2)/1000)) -> 0 | R34: =C34 -> Hot Water | T34: =E34*$T$2 -> 0 | U34: =F34*$T$2 -> 0
C35: Cooktops | E35: ='Calculations Student Accom'!C52*0.277776 -> 0 | F35: =IF('Calculations Student Accom'!G48="Gas",'Calculations Student Accom'!G52*0.277776,'Calculations Student Accom'!G52) -> 0 | H35: =C35 -> Cooktops | J35: =(E35*3.6*$J$3)/1000 -> 0 | K35: =IF('Calculations Retail'!G62="Gas",((F35*3.6*$J$3)/1000),((F35*$J$2)/1000)) -> 0 | M35: =H35 -> Cooktops | O35: =J35 -> 0 | P35: =IF('Calculations Student Accom'!G48="Gas",(K35),IF('Inputs Non-Residential'!D16="Whole Development",((F35*$J$4)/1000),((F35*$J$2)/1000))) -> 0 | R35: =C35 -> Cooktops | T35: =E35*3.6*$Y$2 -> 0 | U35: =IF('Calculations Student Accom'!G48="Gas",'Totals Non-Residential'!F35*3.6*$Y$2,'Totals Non-Residential'!F35*$T$2) -> 0
C36: Total | E36: =SUM(E29:E35) -> 0 | F36: =SUM(F29:F35) -> 0 | H36: =C36 -> Total | J36: =SUM(J29:J35) -> 0 | K36: =SUM(K29:K35) -> 0 | M36: =H36 -> Total | O36: =SUM(O29:O35) -> 0 | P36: =SUM(P29:P35) -> 0 | R36: =C36 -> Total | T36: =E36*$T$2 -> 0 | U36: =F36*$T$2 -> 0
C38: Educational
C39: Energy Use (kWh/yr) | E39: Min. BCA 2022 Compliance | F39: ='Inputs Non-Residential'!D5 -> 0 | H39: GHG Emissions (eqtCO2) | J39: Min. BCA 2022 Compliance | K39: ='Inputs Non-Residential'!D5 -> 0 | M39: GHG Emissions (eqtCO2) With GP | O39: Min. BCA 2022 Compliance | P39: ='Inputs Non-Residential'!D5 -> 0 | R39: Energy Cost | T39: Min. BCA 2022 Compliance | U39: ='Inputs Non-Residential'!D5 -> 0
C40: Heating & Cooling (Elec) | E40: ='Calculations Educational'!C9 -> 0 | F40: ='Calculations Educational'!G9 -> 0 | H40: =C40 -> Heating & Cooling (Elec) | J40: =(E40*$J$2)/1000 -> 0 | K40: =(F40*$J$2)/1000 -> 0 | M40: =H40 -> Heating & Cooling (Elec) | O40: =(E40*$J$2)/1000 -> 0 | P40: =IF('Inputs Non-Residential'!$D$16="Whole Development",((F40*$J$4)/1000),((F40*$J$2)/1000)) -> 0 | R40: =C40 -> Heating & Cooling (Elec) | T40: =E40*$T$2 -> 0 | U40: =F40*$T$2 -> 0
C41: Heating & Cooling (Gas) | E41: ='Calculations Educational'!C17*0.277776 -> 0 | F41: ='Calculations Educational'!G17*0.277776 -> 0 | H41: Heating & Cooling (Gas) | J41: =('Calculations Educational'!C17*J3)/1000 -> 0 | K41: =('Calculations Educational'!G17*J3)/1000 -> 0 | M41: Heating & Cooling (Gas) | O41: =J41 -> 0 | P41: =K41 -> 0 | R41: Heating & Cooling (Gas) | T41: ='Calculations Educational'!C17*$Y$2 -> 0 | U41: ='Calculations Educational'!G17*$Y$2 -> 0
C42: Fans | E42: ='Calculations Educational'!C21 -> 0 | F42: ='Calculations Educational'!G21 -> 0 | H42: Fans | J42: =(E42*$J$2)/1000 -> 0 | K42: =(F42*$J$2)/1000 -> 0 | M42: Fans | O42: =(E42*$J$2)/1000 -> 0 | P42: =IF('Inputs Non-Residential'!$D$16="Whole Development",((F42*$J$4)/1000),((F42*$J$2)/1000)) -> 0 | R42: Fans | T42: =E42*$T$2 -> 0 | U42: =F42*$T$2 -> 0
C43: Appliances | E43: ='Calculations Educational'!C27 -> 0 | F43: ='Calculations Educational'!G27 -> 0 | H43: Appliances | J43: =(E43*$J$2)/1000 -> 0 | K43: =(F43*$J$2)/1000 -> 0 | M43: Appliances | O43: =(E43*$J$2)/1000 -> 0 | P43: =IF('Inputs Non-Residential'!$D$16="Whole Development",((F43*$J$4)/1000),((F43*$J$2)/1000)) -> 0 | R43: Appliances | T43: =E43*$T$2 -> 0 | U43: =F43*$T$2 -> 0
C44: Lighting | E44: ='Calculations Retail'!C57 -> 0 | F44: ='Calculations Retail'!G57 -> 0 | H44: =C44 -> Lighting | J44: =(E44*$J$2)/1000 -> 0 | K44: =(F44*$J$2)/1000 -> 0 | M44: =H44 -> Lighting | O44: =(E44*$J$2)/1000 -> 0 | P44: =IF('Inputs Non-Residential'!$D$16="Whole Development",((F44*$J$4)/1000),((F44*$J$2)/1000)) -> 0 | R44: =C44 -> Lighting | T44: =E44*$T$2 -> 0 | U44: =F44*$T$2 -> 0
C45: Hot Water | E45: ='Calculations Educational'!C44 -> 0 | F45: ='Calculations Educational'!G44 -> 0 | H45: =C45 -> Hot Water | J45: =(E45*$J$2)/1000 -> 0 | K45: =(F45*$J$2)/1000 -> 0 | M45: =H45 -> Hot Water | O45: =(E45*$J$2)/1000 -> 0 | P45: =IF('Inputs Non-Residential'!$D$16="Whole Development",((F45*$J$4)/1000),((F45*$J$2)/1000)) -> 0 | R45: =C45 -> Hot Water | T45: =E45*$T$2 -> 0 | U45: =F45*$T$2 -> 0
C46: Total | E46: =SUM(E40:E45) -> 0 | F46: =SUM(F40:F45) -> 0 | H46: =C46 -> Total | J46: =SUM(J40:J45) -> 0 | K46: =SUM(K40:K45) -> 0 | M46: =H46 -> Total | O46: =SUM(O40:O45) -> 0 | P46: =SUM(P40:P45) -> 0 | R46: =C46 -> Total | T46: =E46*$T$2 -> 0 | U46: =F46*$T$2 -> 0
...

Sheet Drop down
J2: Total ACE MJ/m2
J3: 3 | K3: 7 | L3: 7.5 | M3: 8
B4: Type of HVAC system (resi) | C4: Standard COP | I4: FR Climate Zone | J4: 3 | K4: 7 | L4: 7.5 | M4: 8
B5: Split system | C5: 3.1 | I5: 21 Melbourne | J5: 199 | K5: 62 | L5: 52 | M5: 44
B6: VRV/VRF | C6: 3.3 | I6: 60 Tullamarine | J6: 279 | K6: 55 | L6: 47 | M6: 37
B7: Hydronic heating (heat pump) | C7: 2.5 | I7: 62 Moorabbin Airport | J7: 262 | K7: 99 | L7: 84 | M7: 69
B8: Hydronic heating (gas) | C8: 0.8
I9: Climate Zone | J9: Retail | K9: Office | L9: Communal Areas | M9: Aged Care | N9: Educational | O9: Student Accom
I10: 6 | J10: =Averages!H12 -> 28.223452 | K10: 16.7 | L10: 20 | M10: =Averages!H40 -> 28.316456 | N10: =Averages!Q15 -> 11.504649 | O10: =Averages!Q23 -> 33.538978
B11: Hot water system | C11: Standard COP | I11: 7 | J11: =Averages!H13 -> 0
B12: Heat pump | C12: 2.5
B13: Electric Instantaeous | C13: 1
B14: Gas | C14: 0.8 | I14: Carbon Neutral
I15: Whole Development
B16: Cooktops | C16: Standard Energy use | D16: Commercial Kitchen | E16: Column1 | I16: Base Building
B17: Electric induction | C17: 0.35 | D17: 3.5 | E17: kW/h
B18: Electric convection | C18: =C17*1.1 -> 0.385 | D18: 25 | E18: kW/h
B19: Gas | C19: 6 | D19: =2*14.4 -> 28.8 | E19: MJ/hr
B20: None | C20: 0 | D20: 0 | E20: kW/h
B22: Type of HVAC system retail | C22: COP
B23: Split system | C23: 3.1
B24: VRV/VRF | C24: 3.4

Sheet Averages
B3: Retail | C3: Area (m2) | D3: Heating (kWh) | E3: Cooling (kWh) | F3: Heating (kWhm2) | G3: Cooling (kWh/m2) | H3: Total H&C (kWh/m2) | K3: Educational | L3: Area (m2) | M3: Heating (kWh) | N3: Cooling (kWh) | O3: Heating (kWhm2) | P3: Cooling (kWh/m2) | Q3: Total H&C (kWh/m2)
B4: 786-794 Nicholson St, Fitzroy | C4: 184 | D4: 5460.52 | E4: 2316.9 | F4: =D4/C4 -> 29.676739 | G4: =E4/C4 -> 12.591848 | H4: =SUM(D4:E4)/C4 -> 42.268587 | K4: Kolbe | L4: 2119.31 | M4: 46633.8 | N4: 17577.3 | O4: =M4/L4 -> 22.004237 | P4: =N4/L4 -> 8.2938787 | Q4: =O4+P4 -> 30.298116
B5: 303 Collins St, Melbourne | C5: 2272 | D5: 51882 | E5: 9964 | F5: =D5/C5 -> 22.835387 | G5: =E5/C5 -> 4.3855634 | H5: =SUM(D5:E5)/C5 -> 27.220951 | K5: Eastborne Primary | L5: 544 | M5: 1711 | N5: 1391 | O5: =M5/L5 -> 3.1452206 | P5: =N5/L5 -> 2.5569853 | Q5: =O5+P5 -> 5.7022059
B6: 22 Black St | C6: 35.3 | D6: 261.29 | E6: 1171.36 | F6: =D6/C6 -> 7.401983 | G6: =E6/C6 -> 33.183003 | H6: =SUM(D6:E6)/C6 -> 40.584986 | K6: St Joseph's College | L6: 2864 | M6: 23637 | N6: 11480 | O6: =M6/L6 -> 8.2531425 | P6: =N6/L6 -> 4.0083799 | Q6: =O6+P6 -> 12.261522
B7: 846-858 Glenferrie Rd, Hawthorn | C7: 1038 | D7: 2692 | E7: 9544 | F7: =D7/C7 -> 2.5934489 | G7: =E7/C7 -> 9.194605 | H7: =SUM(D7:E7)/C7 -> 11.788054 | K7: McKinnon Primary | L7: 753 | M7: 1635 | N7: 6879 | O7: =M7/L7 -> 2.1713147 | P7: =N7/L7 -> 9.1354582 | Q7: =O7+P7 -> 11.306773
B8: 8 Egan St | C8: 311 | D8: 2808 | E8: 855 | F8: =D8/C8 -> 9.0289389 | G8: =E8/C8 -> 2.7491961 | H8: =SUM(D8:E8)/C8 -> 11.778135 | K8: Clayton South Primary | L8: 1224 | M8: 4523 | N8: 9481 | O8: =M8/L8 -> 3.6952614 | P8: =N8/L8 -> 7.745915 | Q8: =O8+P8 -> 11.441176
B9: 35-37 Mount St | C9: 50 | D9: 1282 | E9: 503 | F9: =D9/C9 -> 25.64 | G9: =E9/C9 -> 10.06 | H9: =SUM(D9:E9)/C9 -> 35.7 | K9: Gisborne Secondary | L9: 452 | M9: 2109 | N9: 1663 | O9: =M9/L9 -> 4.6659292 | P9: =N9/L9 -> 3.6792035 | Q9: =O9+P9 -> 8.3451327
F10: =D10/C10 -> #DIV/0! | G10: =E10/C10 -> #DIV/0! | H10: =SUM(D10:E10)/C10 -> #DIV/0! | K10: Casey Central Primary | L10: 878 | M10: 3288 | N10: 4284 | O10: =M10/L10 -> 3.7448747 | P10: =N10/L10 -> 4.8792711 | Q10: =O10+P10 -> 8.6241458
F11: =D11/C11 -> #DIV/0! | G11: =E11/C11 -> #DIV/0! | H11: =SUM(D11:E11)/C11 -> #DIV/0! | K11: Clyde Creek North Primary | L11: =1001+1001+1001+1562+1403 -> 5968 | M11: =3921+3932+3985+5406+1836 -> 19080 | N11: =3685+3659+3526+5950+882+873 -> 18575 | O11: =M11/L11 -> 3.1970509 | P11: =N11/L11 -> 3.112433 | Q11: =O11+P11 -> 6.3094839
G12: Average | H12: =AVERAGE(H4:H9) -> 28.223452 | K12: Clyde North | L12: =878+1083+1083+1485+1338 -> 5867 | M12: =3283+4159+4176+5549+6437+1439 -> 25043 | N12: =4334+6148+5966+5925+6873 -> 29246 | O12: =M12/L12 -> 4.2684507 | P12: =N12/L12 -> 4.9848304 | Q12: =O12+P12 -> 9.2532811
B14: Office | C14: Area (m2) | D14: Heating (kWh) | E14: Cooling (kWh) | F14: Heating (kWhm2) | G14: Cooling (kWh/m2) | H14: Total H&C (kWh/m2)
B15: 14 Martin St, Heidelberg Rd | C15: 2553 | D15: 14465 | E15: 9529 | F15: =D15/C15 -> 5.6658833 | G15: =E15/C15 -> 3.7324716 | H15: =SUM(D15:E15)/C15 -> 9.3983549 | P15: Average | Q15: =AVERAGE(Q4:Q12) -> 11.504649
B16: 14-18 Smith St | C16: 487 | D16: 19993 | E16: 5473 | F16: =D16/C16 -> 41.053388 | G16: =E16/C16 -> 11.238193 | H16: =SUM(D16:E16)/C16 -> 52.291581
B17: 13-19 Amsterdam St | C17: 766.42 | D17: 15848.1 | E17: 12766.6 | F17: =D17/C17 -> 20.678088 | G17: =E17/C17 -> 16.657446 | H17: =SUM(D17:E17)/C17 -> 37.335534 | K17: Student accomodation | L17: Area (m2) | M17: Heating (kWh) | N17: Cooling (kWh) | O17: Heating (kWhm2) | P17: Cooling (kWh/m2) | Q17: Total H&C (kWh/m2)
B18: 17-23 Wangaratta St | C18: 1950 | D18: 7359 | E18: 7757 | F18: =D18/C18 -> 3.7738462 | G18: =E18/C18 -> 3.9779487 | H18: =SUM(D18:E18)/C18 -> 7.7517949 | K18: 100-102 Bouverie St | L18: 255 | M18: 4682 | N18: 4504 | O18: =M18/L18 -> 18.360784 | P18: =N18/L18 -> 17.662745 | Q18: =O18+P18 -> 36.023529
B19: 71-89 Moorabool St | C19: 1233 | D19: 9205 | E19: 3387 | F19: =D19/C19 -> 7.4655312 | G19: =E19/C19 -> 2.7469586 | H19: =SUM(D19:E19)/C19 -> 10.21249 | K19: 204-206 King St | L19: 24738 | M19: 583198 | N19: 212362 | O19: =M19/L19 -> 23.574986 | P19: =N19/L19 -> 8.584445 | Q19: =O19+P19 -> 32.159431
B20: 167-169 Cremorne St | C20: 2925 | D20: 23838 | E20: 26637 | F20: =D20/C20 -> 8.1497436 | G20: =E20/C20 -> 9.1066667 | H20: =SUM(D20:E20)/C20 -> 17.25641 | K20: 43 Mackenzie St | L20: 16636 | M20: 692119 | N20: 49460 | O20: =M20/L20 -> 41.603691 | P20: =N20/L20 -> 2.9730704 | Q20: =O20+P20 -> 44.576761
B21: 18-20 Rutland St | C21: 1039 | D21: 4541 | E21: 3915 | F21: =D21/C21 -> 4.3705486 | G21: =E21/C21 -> 3.7680462 | H21: =SUM(D21:E21)/C21 -> 8.1385948 | K21: 21-25 Bouverie St | L21: 10863 | M21: 156227.52 | N21: 76199.3 | O21: =M21/L21 -> 14.381618 | P21: =N21/L21 -> 7.0145724 | Q21: =O21+P21 -> 21.396191
B22: 85 Dover St | C22: 397 | D22: 2053 | E22: 1693 | F22: =D22/C22 -> 5.1712846 | G22: =E22/C22 -> 4.2644836 | H22: =SUM(D22:E22)/C22 -> 9.4357683
B23: 40-50 Rokeby St | C23: 766.42 | D23: 2769.3 | E23: 4953.6 | F23: =D23/C23 -> 3.613293 | G23: =E23/C23 -> 6.4632969 | H23: =SUM(D23:E23)/C23 -> 10.07659 | P23: Average | Q23: =AVERAGE(Q18:Q21) -> 33.538978
B24: 30 Cambridge St | C24: 449 | D24: 1854 | E24: 2041 | F24: =D24/C24 -> 4.1291759 | G24: =E24/C24 -> 4.545657 | H24: =SUM(D24:E24)/C24 -> 8.674833
B25: 32-38 Rokeby St | C25: 3835.6 | D25: 27756.3 | E25: 29468.9 | F25: =D25/C25 -> 7.2364949 | G25: =E25/C25 -> 7.6829961 | H25: =SUM(D25:E25)/C25 -> 14.919491
B26: 46 Gwynne St | C26: 116 | D26: 827 | E26: 913 | F26: =D26/C26 -> 7.1293103 | G26: =E26/C26 -> 7.8706897 | H26: =SUM(D26:E26)/C26 -> 15
G28: Average | H28: =AVERAGE(H15:H26) -> 16.70762
B31: Aged Care | C31: Area (m2) | D31: Heating (kWh) | E31: Cooling (kWh) | F31: Heating (kWhm2) | G31: Cooling (kWh/m2) | H31: Total H&C (kWh/m2)
B32: Romsey Aged Care | C32: 8233 | D32: 162744 | E32: 23443 | F32: =D32/C32 -> 19.767278 | G32: =E32/C32 -> 2.8474432 | H32: =F32+G32 -> 22.614721
B33: 102 Shrives Rd | C33: 10179 | D33: 233638 | E33: 33225 | F33: =D33/C33 -> 22.952942 | G33: =E33/C33 -> 3.2640731 | H33: =F33+G33 -> 26.217015
B34: 20 Tivendale Rd | C34: 8798 | D34: 249184 | E34: 22862 | F34: =D34/C34 -> 28.322801 | G34: =E34/C34 -> 2.5985451 | H34: =F34+G34 -> 30.921346
B35: 175 MacMahons Rd | C35: 6340 | D35: 830914 | E35: 36729 | F35: =D35/C35 -> 131.05899 | G35: =E35/C35 -> 5.7932177 | H35: =F35+G35 -> 136.85221
B36: 52 Golf Rd | C36: 1633 | D36: 39991 | E36: 8051 | F36: =D36/C36 -> 24.489284 | G36: =E36/C36 -> 4.9301898 | H36: =F36+G36 -> 29.419473
B37: 1505 Point Nepean | C37: 16184 | D37: 488511 | E37: 36008 | F37: =D37/C37 -> 30.184812 | G37: =E37/C37 -> 2.2249135 | H37: =F37+G37 -> 32.409726
F38: =D38/C38 -> #DIV/0! | G38: =E38/C38 -> #DIV/0! | H38: =F38+G38 -> #DIV/0!
G40: Average | H40: =AVERAGE(H32:H34,H36:H37) -> 28.316456
