Workbook

Sheet Final Report
D9: ='Totals Residential & Mixed-Use'!F16 -> #N/A | G9: kWh/yr | J9: of residential energy reduction compared to minimum BCA 2022 Compliance.
D17: ='Totals Residential & Mixed-Use'!K63 -> #N/A | F17: GHG emission | L17: reduction in the whole building compared to minimum BCA 2022 Compliance.
D22: ='Totals Residential & Mixed-Use'!Y17 -> #N/A | G22: of operating cost reduction per apartment per year compared to minimum BCA 2022 Compliance.
D24: ='Totals Residential & Mixed-Use'!X17 -> #N/A | G24: of operating cost reduction per apartment per year compared to the Existing Building Stock
T25: *All results are indicative only, based on preliminary assumptions.

Sheet Inputs Residential & Mixed-Use
B3: Development | G3: Location
C5: Development Address
C6: No. of apartments / THs | H6: FR Climate Zone
C7: Average m2 per apartment / TH | E7: m2 | H7: Climate zone
C8: Retail | E8: m2
C9: Office | E9: m2
C10: Conditioned communal space | E10: m2
C11: Unconditioned communal space | E11: m2
C12: Carpark | E12: m2
C13: Services | E13: m2
C14: No. of Lifts
C15: Lift Height | E15: m
C17: Carbon Neutral
B20: Energy
C22: Residential | H22: Retail | L22: Office
C23: Average star rating commitment | E23: Star | H23: % reduction on DTS compliance (heating & cooling only) | I23: 0 | J23: % | L23: % reduction on DTS compliance (heating & cooling only) | N23: %
C24: Average heating load | E24: MJ/m2 | H24: Type of HVAC system | I24: VRV/VRF | L24: Type of HVAC system | M24: VRV/VRF
C25: Average cooling load | E25: MJ/m2 | H25: Efficency of HVAC system | I25: =VLOOKUP(I24,Table13[#All],2,FALSE) -> 3.4 | J25: COP | L25: Efficency of HVAC system | M25: =VLOOKUP(M24,Table13[#All],2,FALSE) -> 3.4 | N25: COP
C26: Type of HVAC system (heating) | D26: Split system | H26: % reduction on lighting power | I26: 0 | J26: % | L26: % reduction on lighting power | M26: 0 | N26: %
C27: Type of HVAC system (cooling) | D27: Split system | H27: Cooktops
C28: Efficency of HVAC system (heating) | D28: =VLOOKUP(D26,Table8[#All],2,FALSE) -> 3.1 | E28: COP | L28: OR
C29: Efficency of HVAC system (cooling) | D29: =VLOOKUP(D27,Table8[#All],2,FALSE) -> 3.1 | E29: COP | H29: OR
C30: % reduction on lighting power | D30: 20 | E30: % | L30: J1V3 Modelling Results
C31: Efficient appliances | D31: N | E31: Y/N | H31: J1V3 Modelling Results | L31: Reference Heating Energy Use (Elec) | N31: kWh/m2
C32: Cooktops | D32: Electric induction | H32: Reference Heating Energy Use (Elec) | J32: kWh/m2 | L32: Reference Cooling Energy Use (Elec) | N32: kWh/m2
C33: Clothes drying Reference (BESS) | E33: kWh | H33: Reference Cooling Energy Use (Elec) | J33: kWh/m2 | L33: Reference Heating Energy Use (Gas) | N33: MJ/m2
C34: Clothes drying proposed (BESS) | E34: kWh | H34: Reference Heating Energy Use (Gas) | J34: MJ/m2 | L34: Reference Cooling Energy Use (Gas) | N34: MJ/m2
H35: Reference Cooling Energy Use (Gas) | J35: MJ/m2 | L35: Reference Fans | N35: kWh/m2
H36: Reference Fans | J36: kWh/m2 | L36: Reference Lighting | N36: kWh/m2
H37: Reference Lighting | J37: kWh/m2
L38: Proposed Heating Energy Use (Elec) | N38: kWh/m2
H39: Proposed Heating Energy Use (Elec) | J39: kWh/m2 | L39: Proposed Cooling Energy Use (Elec) | N39: kWh/m2
C40: Solar PV (whole building) | E40: kWh | H40: Proposed Cooling Energy Use (Elec) | J40: kWh/m2 | L40: Proposed Heating Energy Use (Gas) | N40: MJ/m2
C41: Solar PV (individual systems) | E41: kWh/unit | H41: Proposed Heating Energy Use (Gas) | J41: MJ/m2 | L41: Proposed Cooling Energy Use (Gas) | N41: MJ/m2
H42: Proposed Cooling Energy Use (Gas) | J42: MJ/m2 | L42: Proposed Fans | N42: kWh/m2
H43: Proposed Fans | J43: kWh/m2 | L43: Proposed Lighting | N43: kWh/m2
H44: Proposed Lighting | J44: kWh/m2
B47: Water (BESS)
C49: Residential | H49: Retail | L49: Office | P49: Whole Building
C50: No of occupants | D50: =D6*2.5 -> 0 | E50: Occupants | H50: Type of hot water system | I50: Heat pump | L50: Type of hot water system | M50: Electric Instantaeous
...

Sheet Graphs

Sheet Calculations Residential
B2: Existing Building Stock | F2: Minimum BCA 2022 Compliance | J2: Proposed
B3: Heating and Cooling Demand (kWh) | C3: Quantity | D3: Unit | F3: Heating and Cooling Demand (kWh) | G3: Quantity | H3: Unit | K3: Quantity | L3: Unit
B4: Reference Star Rating | C4: 3 | D4: Star | F4: Reference Star Rating | G4: 7 | H4: Star | J4: Targeted Star Rating | K4: ='Inputs Residential & Mixed-Use'!D23 -> 0 | L4: Star
B5: Climate Zone | C5: ='Inputs Residential & Mixed-Use'!I6 -> 0 | D5: N/A | F5: Climate Zone | G5: ='Inputs Residential & Mixed-Use'!I6 -> 0 | H5: N/A | J5: Climate Zone | K5: ='Inputs Residential & Mixed-Use'!I6 -> 0 | L5: N/A
B6: Heating & Cooling Load | C6: =VLOOKUP('Inputs Residential & Mixed-Use'!I6,Table11[#All],MATCH(C4,'Drop down'!I3:M3,0),FALSE) -> #N/A | D6: MJ/m2 | F6: Heating & Cooling Load | G6: =VLOOKUP('Inputs Residential & Mixed-Use'!I6,Table11[#All],MATCH(G4,'Drop down'!I3:M3,0),FALSE) -> #N/A | H6: MJ/m2 | J6: Heating Load | K6: ='Inputs Residential & Mixed-Use'!D24 -> 0 | L6: MJ/m2
J7: Cooling Load | K7: ='Inputs Residential & Mixed-Use'!D25 -> 0 | L7: MJ/m2
B9: Reference Efficiency HVAC System | C9: 3.1 | D9: COP | F9: Reference Efficiency HVAC System | G9: 3.1 | H9: COP | J9: Efficiency HVAC System (heating) | K9: ='Inputs Residential & Mixed-Use'!D28 -> 3.1 | L9: COP
J10: Efficiency HVAC System (cooling) | K10: ='Inputs Residential & Mixed-Use'!D29 -> 3.1 | L10: COP
B12: Reference Heating & Cooling Energy Use | C12: =((C6*0.2777777778)*'Inputs Residential & Mixed-Use'!D7*'Inputs Residential & Mixed-Use'!D6)/C9 -> #N/A | D12: kWh/yr | F12: Reference Heating & Cooling Energy Use | G12: =((G6*0.2777777778)*'Inputs Residential & Mixed-Use'!D7*'Inputs Residential & Mixed-Use'!D6)/G9 -> #N/A | H12: kWh/yr | J12: Heating & Cooling Energy Use | K12: =(((K6*0.2777777778)*'Inputs Residential & Mixed-Use'!D7*'Inputs Residential & Mixed-Use'!D6)/K9)+(((K7*0.2777777778)*'Inputs Residential & Mixed-Use'!D7*'Inputs Residential & Mixed-Use'!D6)/K10) -> 0 | L12: kWh/yr
B14: Appliances (kWh) | C14: Quantity | D14: Unit | F14: Appliances (kWh) | G14: Quantity | H14: Unit | K14: Quantity | L14: Unit
B15: Reference average power density | C15: 5 | D15: W/m2 | F15: Reference average power density | G15: 5 | H15: W/m2 | J15: Targeted averager power density | K15: =IF('Inputs Residential & Mixed-Use'!D31="Y",'Calculations Residential'!G15*0.8,'Calculations Residential'!G15) -> 5 | L15: W/m2
B16: Average hours of use per day | C16: 8 | D16: hours | F16: Average hours of use per day | G16: 8 | H16: hours | J16: Average hours of use per day | K16: 8 | L16: hours
B18: Reference Appliance Energy Use | C18: =(C15/1000)*C16*365*'Inputs Residential & Mixed-Use'!D7*'Inputs Residential & Mixed-Use'!D6 -> 0 | D18: kWh/yr | F18: Reference Appliance Energy Use | G18: =(G15/1000)*G16*365*'Inputs Residential & Mixed-Use'!D7*'Inputs Residential & Mixed-Use'!D6 -> 0 | H18: kWh/yr | J18: Appliance Energy Use | K18: =(K15/1000)*K16*365*'Inputs Residential & Mixed-Use'!D7*'Inputs Residential & Mixed-Use'!D6 -> 0 | L18: kWh/yr
B20: Lighting (kWh) | C20: Quantity | D20: Unit | F20: Lighting (kWh) | G20: Quantity | H20: Unit | K20: Quantity | L20: Unit
B21: Reference Lighting Power Density | C21: 5 | D21: W/m2 | F21: Reference Lighting Power Density | G21: 5 | H21: W/m2 | J21: Lighting Power Density | K21: =G21*(1-('Inputs Residential & Mixed-Use'!D30/100)) -> 4 | L21: W/m2
B22: Hours of Operation per Day (Living) | C22: 10.2 | D22: hours | F22: Hours of Operation per Day (Living) | G22: 10.2 | H22: hours | J22: Hours of Operation per Day (Living) | K22: 10.2 | L22: hours
B23: Hours of Operation per Day (Sleeping) | C23: 6.2 | D23: hours | F23: Hours of Operation per Day (Sleeping) | G23: 6.2 | H23: hours | J23: Hours of Operation per Day (Sleeping) | K23: 6.2 | L23: hours
B25: Reference Lighting Energy Use | C25: =((C21/1000)*C22*'Inputs Residential & Mixed-Use'!D6*('Inputs Residential & Mixed-Use'!D7*0.7)*365)+((C21/1000)*C23*'Inputs Residential & Mixed-Use'!D6*('Inputs Residential & Mixed-Use'!D7*0.3)*365) -> 0 | D25: kWh/yr | F25: Reference Lighting Energy Use | G25: =((G21/1000)*G22*'Inputs Residential & Mixed-Use'!D6*('Inputs Residential & Mixed-Use'!D7*0.7)*365)+((G21/1000)*G23*'Inputs Residential & Mixed-Use'!D6*('Inputs Residential & Mixed-Use'!D7*0.3)*365) -> 0 | H25: kWh/yr | J25: Lighting Energy Use | K25: =((K21/1000)*K22*'Inputs Residential & Mixed-Use'!D6*('Inputs Residential & Mixed-Use'!D7*0.7)*365)+((K21/1000)*K23*'Inputs Residential & Mixed-Use'!D6*('Inputs Residential & Mixed-Use'!D7*0.3)*365) -> 0 | L25: kWh/yr
B27: Hot Water (kWh) | C27: Quantity | D27: Unit | F27: Hot Water (kWh) | G27: Quantity | H27: Unit | K27: Quantity | L27: Unit
B28: Reference Total Hot Water Use | C28: ='Inputs Residential & Mixed-Use'!D50*60*365*1.25 -> 0 | D28: L/yr | F28: Reference Total Hot Water Use | G28: ='Inputs Residential & Mixed-Use'!D50*60*365 -> 0 | H28: L/yr | J28: Total Hot Water Use | K28: =G28*(1-('Inputs Residential & Mixed-Use'!D53/100)) -> 0 | L28: L/yr
B29: Cold Water Temp | C29: 15 | D29: C | F29: Cold Water Temp | G29: 15 | H29: C | J29: Cold Water Temp | K29: 15 | L29: C
B30: Hot Water Temp | C30: 60 | D30: C | F30: Hot Water Temp | G30: 60 | H30: C | J30: Hot Water Temp | K30: 60 | L30: C
B31: Water Heat Capacity | C31: 0.004186 | D31: MJ/L/C | F31: Water Heat Capacity | G31: 0.004186 | H31: MJ/L/C | J31: Water Heat Capacity | K31: 0.004186 | L31: MJ/L/C
B32: Reference Energy Required | C32: =(C28*C31*(C30-C29)) -> 0 | D32: MJ/yr | F32: Reference Energy Required | G32: =(G28*G31*(G30-G29))/3.6 -> 0 | H32: kWh/yr | J32: Energy Required | K32: =(K28*K31*(K30-K29))/3.6 -> 0 | L32: kWh/yr
B34: Reference Hot Water System Efficiency | C34: 0.6 | D34: COP | F34: Reference Hot Water System Efficiency | G34: 1 | H34: COP | J34: Hot Water System Efficiency | K34: ='Inputs Residential & Mixed-Use'!D52 -> #N/A | L34: COP
J35: Distribution Losses | K35: 0.1
B37: Reference Hot Water Energy Use | C37: =C32/C34 -> 0 | D37: MJ/yr | F37: Reference Hot Water Energy Use | G37: =G32/G34 -> 0 | H37: kWh/yr | J37: Hot Water Energy Use | K37: =IF('Inputs Residential & Mixed-Use'!D51="Heat pump",(K32/K34)*(1+K35),(K32/K34)) -> #N/A | L37: kWh/yr
B39: Cooktops (kWh) | C39: Quantity | D39: Unit | F39: Cooktops (kWh) | G39: Quantity | H39: Unit
B40: Energy source | C40: Gas | F40: Energy source | G40: Electric | J40: Energy source | K40: =IF('Inputs Residential & Mixed-Use'!D32="Gas","Gas","Electric") -> Electric
B41: Energy Use system | C41: 6 | D41: MJ/hr | F41: Energy Use system | G41: ='Drop down'!C18 -> 0.385 | H41: kW/h | J41: Energy use system | K41: =VLOOKUP('Inputs Residential & Mixed-Use'!D32,Table10[#All],2,FALSE) -> 0.35 | L41: =IF(K40="Gas", "MJ/yr", "kWh/yr") -> kWh/yr
B42: Average hours of use per day | C42: 1.5 | D42: hours/day | F42: Average hours of use per day | G42: 1.5 | H42: hours/day | J42: Average hours of use per day | K42: 1.5 | L42: hours/day
B44: Reference Cooktop Energy Use | C44: =C41*C42*365*'Inputs Residential & Mixed-Use'!D6 -> 0 | D44: MJ/yr | F44: Reference Cooktop Energy Use | G44: =G41*G42*365*'Inputs Residential & Mixed-Use'!D6 -> 0 | H44: kWh/yr | J44: Cooktop Energy Use | K44: =IF(K40="Electric",(K41*K42*365*'Inputs Residential & Mixed-Use'!D6),(K41*K42*'Inputs Residential & Mixed-Use'!D6*365)) -> 0 | L44: =IF(K40="Gas", "MJ/yr", "kWh/yr") -> kWh/yr
B46: Clothes Drying (kWh) | F46: Clothes Drying (kWh)
B47: Reference clothes drying | C47: =G47 -> 0 | D47: kWh/yr | F47: Reference clothes drying | G47: ='Inputs Residential & Mixed-Use'!D33 -> 0 | H47: kWh/yr | J47: Clothes drying | K47: ='Inputs Residential & Mixed-Use'!D34 -> 0 | L47: kWh/yr

Sheet Calculations Retail
B2: Reference | F2: Proposed
B3: Heating and Cooling Demand (Elec) (kWh) | C3: Quantity | D3: Unit | G3: Quantity | H3: Unit
B4: Climate Zone | C4: ='Inputs Residential & Mixed-Use'!I7 -> 0 | D4: N/A | F4: Climate Zone | G4: ='Inputs Residential & Mixed-Use'!I7 -> 0 | H4: N/A
B5: Heating & Cooling Load | C5: =VLOOKUP(C4,Table12[#All],2,FALSE) -> #N/A | D5: kWh/m2 | F5: Heating & Cooling Load | G5: =VLOOKUP(C4,Table12[#All],2,FALSE)*(1-('Inputs Residential & Mixed-Use'!I23/100)) -> #N/A | H5: kWh/m2
B7: Reference Efficiency HVAC System | C7: 3.1 | D7: COP | F7: Efficiency HVAC System (heating) | G7: ='Inputs Residential & Mixed-Use'!I25 -> 3.4 | H7: COP
B9: Reference Heating & Cooling Energy Use | C9: =IF(SUM('Inputs Residential & Mixed-Use'!I32:I35)=0,(C5/C7)*'Inputs Residential & Mixed-Use'!D8,(('Inputs Residential & Mixed-Use'!I32+'Inputs Residential & Mixed-Use'!I33)*'Inputs Residential & Mixed-Use'!D8)) -> #N/A | D9: kWh/yr | F9: Heating & Cooling Energy Use | G9: =IF(SUM('Inputs Residential & Mixed-Use'!I39:I42)=0,(G5/G7)*'Inputs Residential & Mixed-Use'!D8,(('Inputs Residential & Mixed-Use'!I39+'Inputs Residential & Mixed-Use'!I40)*'Inputs Residential & Mixed-Use'!D8)) -> #N/A | H9: kWh/yr
B11: Heating and Cooling Demand (Gas) (MJ) | C11: Quantity | D11: Unit | G11: Quantity | H11: Unit
B12: Climate Zone | C12: ='Inputs Residential & Mixed-Use'!I14 -> 0 | D12: N/A | F12: Climate Zone | G12: ='Inputs Residential & Mixed-Use'!I14 -> 0 | H12: N/A
B13: Heating & Cooling Load | C13: =SUM('Inputs Residential & Mixed-Use'!I34:I35) -> 0 | D13: MJ/m2 | F13: Heating & Cooling Load | G13: =SUM9 -> 0 | H13: MJ/m2
B15: Reference Efficiency HVAC System | C15: 3.1 | D15: COP | F15: Efficiency HVAC System (heating) | G15: ='Inputs Residential & Mixed-Use'!I25 -> 3.4 | H15: COP
B17: Reference Heating & Cooling Energy Use | C17: =IF(SUM('Inputs Residential & Mixed-Use'!I32:I35)=0,((C13/C15)*'Inputs Residential & Mixed-Use'!D8),(('Inputs Residential & Mixed-Use'!I39+'Inputs Residential & Mixed-Use'!I40)*'Inputs Residential & Mixed-Use'!D8)) -> 0 | D17: MJ/yr | F17: Heating & Cooling Energy Use | G17: =IF(SUM('Inputs Residential & Mixed-Use'!I39:I42)=0,((G13/G15)*'Inputs Residential & Mixed-Use'!D8),(('Inputs Residential & Mixed-Use'!I46+'Inputs Residential & Mixed-Use'!I47)*'Inputs Residential & Mixed-Use'!D8)) -> 0 | H17: MJ/yr
B19: Fan Energy (kWh)
B21: Reference Fan Energy | C21: ='Inputs Residential & Mixed-Use'!I36*'Inputs Residential & Mixed-Use'!D8 -> 0 | D21: kWh/yr | F21: Proposed Fan Energy | G21: ='Inputs Residential & Mixed-Use'!I43*'Inputs Residential & Mixed-Use'!D8 -> 0 | H21: kWh/yr
B23: Lighting (kWh) | C23: Quantity | D23: Unit | G23: Quantity | H23: Unit
B24: Reference Lighting Power Density | C24: 14 | D24: W/m2 | F24: Lighting Power Density | G24: =C24*(1-('Inputs Residential & Mixed-Use'!I26/100)) -> 14 | H24: W/m2
B25: Hours of Operation per Day | C25: 8 | D25: hours | F25: Hours of Operation per Day | G25: 8 | H25: hours
B27: Reference Lighting Energy Use | C27: =IF('Inputs Residential & Mixed-Use'!I37=0,((C24/1000)*C25*'Inputs Residential & Mixed-Use'!D8*365),('Inputs Residential & Mixed-Use'!I37*'Inputs Residential & Mixed-Use'!D8)) -> 0 | D27: kWh/yr | F27: Lighting Energy Use | G27: =IF('Inputs Residential & Mixed-Use'!I44=0,((G24/1000)*G25*'Inputs Residential & Mixed-Use'!D8*365),'Inputs Residential & Mixed-Use'!I44*'Inputs Residential & Mixed-Use'!D8) -> 0 | H27: kWh/yr
B29: Hot Water (kWh) | C29: Quantity | D29: Unit | G29: Quantity | H29: Unit
B30: Reference Total Hot Water Use | C30: =('Inputs Residential & Mixed-Use'!I52*0.26*20*4.5*365) -> 0 | D30: L/yr | F30: Total Hot Water Use | G30: =C30*(1-('Inputs Residential & Mixed-Use'!I53/100)) -> 0 | H30: L/yr
B31: Cold Water Temp | C31: 15 | D31: C | F31: Cold Water Temp | G31: 15 | H31: C
B32: Hot Water Temp | C32: 60 | D32: C | F32: Hot Water Temp | G32: 60 | H32: C
B33: Water Heat Capacity | C33: 0.004186 | D33: MJ/L/C | F33: Water Heat Capacity | G33: 0.004186 | H33: MJ/L/C
B34: Reference Energy Required | C34: =(C30*C33*(C32-C31))/3.6 -> 0 | D34: kWh/yr | F34: Energy Required | G34: =(G30*G33*(G32-G31))/3.6 -> 0 | H34: kWh/yr
B36: Reference Hot Water System Efficiency | C36: 1 | D36: COP | F36: Hot Water System Efficiency | G36: ='Inputs Residential & Mixed-Use'!I51 -> 2.5 | H36: COP
B38: Reference Hot Water Energy Use | C38: =C34/C36 -> 0 | D38: kWh/yr | F38: Hot Water Energy Use | G38: =G34/G36 -> 0 | H38: kWh/yr
B40: Cooktops (kWh) | C40: Quantity | D40: Unit
B41: Type | C41: Gas | F41: Type | G41: ='Inputs Residential & Mixed-Use'!I27 -> 0
B42: Energy Source | C42: Gas | F42: Energy Source | G42: =IF('Inputs Residential & Mixed-Use'!I27="Gas","Gas","Electric") -> Electric
B43: Energy Use system | C43: ='Drop down'!D19 -> 28.8 | D43: MJ/hr | F43: Energy use system | G43: =VLOOKUP(G41,Table10[#All],3,FALSE) -> #N/A | H43: =VLOOKUP(G41,Table10[#All],4,FALSE) -> #N/A
B44: Average hours of use per day | C44: 6 | D44: hours/day | F44: Average hours of use per day | G44: 6 | H44: hours/day
B46: Reference Cooktop Energy Use | C46: =IF('Inputs Residential & Mixed-Use'!I27="None",0,(C43*C44*365)) -> 63072 | D46: =IF(C42="Gas","MJ/yr","kWh/yr") -> MJ/yr | F46: Cooktop Energy Use | G46: =IF(G42="Gas",(G43*G44*365),(G43*G44*365)) -> #N/A | H46: =IF(G42="Gas","MJ/yr","kWh/yr") -> kWh/yr

Sheet Calculations Office
B3: Heating and Cooling Demand (Elec) (kWh) | C3: Quantity | D3: Unit | G3: Quantity | H3: Unit
B4: Climate Zone | C4: ='Inputs Residential & Mixed-Use'!I7 -> 0 | D4: N/A | F4: Climate Zone | G4: ='Inputs Residential & Mixed-Use'!I7 -> 0 | H4: N/A
B5: Heating & Cooling Load | C5: =VLOOKUP(C4,Table12[#All],3,FALSE) -> #N/A | D5: kWh/m2 | F5: Heating & Cooling Load | G5: =VLOOKUP(C4,Table12[#All],3,FALSE)*(1-('Inputs Residential & Mixed-Use'!M23/100)) -> #N/A | H5: kWh/m2
B7: Reference Efficiency HVAC System | C7: 3.1 | D7: COP | F7: Efficiency HVAC System (heating) | G7: ='Inputs Residential & Mixed-Use'!M25 -> 3.4 | H7: COP
B9: Reference Heating & Cooling Energy Use | C9: =IF(SUM('Inputs Residential & Mixed-Use'!M31:M34)=0,(C5*'Inputs Residential & Mixed-Use'!D9)/C7,(('Inputs Residential & Mixed-Use'!M31+'Inputs Residential & Mixed-Use'!M32)*'Inputs Residential & Mixed-Use'!D9)) -> #N/A | D9: kWh/yr | F9: Heating & Cooling Energy Use | G9: =IF(SUM('Inputs Residential & Mixed-Use'!M31:M34)=0,(G5*'Inputs Residential & Mixed-Use'!D9)/G7,(('Inputs Residential & Mixed-Use'!M38+'Inputs Residential & Mixed-Use'!M39)*'Inputs Residential & Mixed-Use'!D9)) -> #N/A | H9: kWh/yr
B11: Heating and Cooling Demand (Gas) (MJ) | C11: Quantity | D11: Unit | G11: Quantity | H11: Unit
B12: Climate Zone | C12: ='Inputs Residential & Mixed-Use'!I14 -> 0 | D12: N/A | F12: Climate Zone | G12: ='Inputs Residential & Mixed-Use'!I14 -> 0 | H12: N/A
B13: Heating & Cooling Load | C13: =SUM('Inputs Residential & Mixed-Use'!M33:M34) -> 0 | D13: MJ/m2 | F13: Heating & Cooling Load | G13: =SUM('Inputs Residential & Mixed-Use'!M40:M41) -> 0 | H13: MJ/m2
B15: Reference Efficiency HVAC System | C15: 3.1 | D15: COP | F15: Efficiency HVAC System (heating) | G15: ='Inputs Residential & Mixed-Use'!I33 -> 0 | H15: COP
B17: Reference Heating & Cooling Energy Use | C17: =SUM('Inputs Residential & Mixed-Use'!M33:M34)*'Inputs Residential & Mixed-Use'!D9 -> 0 | D17: MJ/yr | F17: Heating & Cooling Energy Use | G17: =SUM('Inputs Residential & Mixed-Use'!M40:M41)*'Inputs Residential & Mixed-Use'!D9 -> 0 | H17: MJ/yr
B19: Fan Energy (kWh)
B21: Reference Fan Energy | C21: ='Inputs Residential & Mixed-Use'!M35*'Inputs Residential & Mixed-Use'!D9 -> 0 | D21: kWh/yr | F21: Proposed Fan Energy | G21: ='Inputs Residential & Mixed-Use'!M42*'Inputs Residential & Mixed-Use'!D9 -> 0 | H21: kWh/yr
B23: Appliances (kWh) | C23: Quantity | D23: Unit | G23: Quantity | H23: Unit
B24: Reference average power density | C24: 11 | D24: W/m2 | F24: Targeted averager power density | G24: 11 | H24: W/m2
B25: Average hours of use per day | C25: 8 | D25: hours | F25: Average hours of use per day | G25: 8 | H25: hours
B27: Reference Appliance Energy Use | C27: =(C24/1000)*(C25+((24-C25)*0.25))*(365-104)*'Inputs Residential & Mixed-Use'!D9 -> 0 | D27: kWh/yr | F27: Appliance Energy Use | G27: =(G24/1000)*(G25+((24-G25)*0.25))*(365-104)*'Inputs Residential & Mixed-Use'!D9 -> 0 | H27: kWh/yr
B29: Lighting (kWh) | C29: Quantity | D29: Unit | G29: Quantity | H29: Unit
B30: Reference Lighting Power Density | C30: 4.5 | D30: W/m2 | F30: Lighting Power Density | G30: =C30*(1-('Inputs Residential & Mixed-Use'!M26/100)) -> 4.5 | H30: W/m2
B31: Hours of Operation per Day | C31: 10 | D31: hours | F31: Hours of Operation per Day (Living) | G31: 10 | H31: hours
B33: Reference Lighting Energy Use | C33: =IF('Inputs Residential & Mixed-Use'!M36=0,((C30/1000)*C31*'Inputs Residential & Mixed-Use'!D9*(365-104)),('Inputs Residential & Mixed-Use'!M36*'Inputs Residential & Mixed-Use'!D9)) -> 0 | D33: kWh/yr | F33: Lighting Energy Use | G33: =IF('Inputs Residential & Mixed-Use'!M43=0,((G30/1000)*G31*'Inputs Residential & Mixed-Use'!D9*(365-104)),('Inputs Residential & Mixed-Use'!M43*'Inputs Residential & Mixed-Use'!D9)) -> 0 | H33: kWh/yr
B35: Hot Water (kWh) | C35: Quantity | D35: Unit | G35: Quantity | H35: Unit
B36: Reference Total Hot Water Use | C36: ='Inputs Residential & Mixed-Use'!M52*4*(365-104) -> 0 | D36: L/yr | F36: Total Hot Water Use | G36: =C36*(1-('Inputs Residential & Mixed-Use'!M53/100)) -> 0 | H36: L/yr
B37: Cold Water Temp | C37: 15 | D37: C | F37: Cold Water Temp | G37: 15 | H37: C
B38: Hot Water Temp | C38: 60 | D38: C | F38: Hot Water Temp | G38: 60 | H38: C
B39: Water Heat Capacity | C39: 0.004186 | D39: MJ/L/C | F39: Water Heat Capacity | G39: 0.004186 | H39: MJ/L/C
B40: Reference Energy Required | C40: =(C36*C39*(C38-C37))/3.6 -> 0 | D40: kWh/yr | F40: Energy Required | G40: =(G36*G39*(G38-G37))/3.6 -> 0 | H40: kWh/yr
B42: Reference Hot Water System Efficiency | C42: 1 | D42: COP | F42: Hot Water System Efficiency | G42: ='Inputs Residential & Mixed-Use'!M51 -> 1 | H42: COP
B44: Reference Hot Water Energy Use | C44: =C40/C42 -> 0 | D44: kWh/yr | F44: Hot Water Energy Use | G44: =G40/G42 -> 0 | H44: kWh/yr

Sheet Calculations Communal
B2: Heating and Cooling Demand (kWh) | C2: Quantity | D2: Unit | G2: Quantity | H2: Unit
B3: Climate Zone | C3: ='Inputs Residential & Mixed-Use'!I7 -> 0 | D3: N/A | F3: Climate Zone | G3: ='Inputs Residential & Mixed-Use'!I7 -> 0 | H3: N/A
B4: Heating & Cooling Load | C4: =VLOOKUP(C3,Table12[#All],4,FALSE) -> #N/A | D4: kWh/m2 | F4: Heating & Cooling Load | G4: =VLOOKUP(C3,Table12[#All],4,FALSE)*(1-('Inputs Residential & Mixed-Use'!M22/100)) -> #N/A | H4: kWh/m2
B6: Reference Efficiency HVAC System | C6: 3.1 | D6: COP | F6: Efficiency HVAC System (heating) | G6: =3.1 -> 3.1 | H6: COP
B8: Reference Heating & Cooling Energy Use | C8: =(C4*'Inputs Residential & Mixed-Use'!D10)/C6 -> #N/A | D8: kWh/yr | F8: Heating & Cooling Energy Use | G8: =(G4*'Inputs Residential & Mixed-Use'!D10)/G6 -> #N/A | H8: kWh/yr
B10: Lighting (kWh) | C10: Quantity | D10: Unit | G10: Quantity | H10: Unit
B11: Reference Lighting Power Density | C11: 5 | D11: W/m2 | F11: Lighting Power Density | G11: 5 | H11: W/m2
B12: Hours of Operation per Day | C12: 8 | D12: hours | F12: Hours of Operation per Day (Living) | G12: 8 | H12: hours
B14: Reference Lighting Energy Use | C14: =(C11/1000)*365*C12*('Inputs Residential & Mixed-Use'!D11+'Inputs Residential & Mixed-Use'!D10) -> 0 | D14: kWh/yr | F14: Lighting Energy Use | G14: =(G11/1000)*365*G12*('Inputs Residential & Mixed-Use'!D11+'Inputs Residential & Mixed-Use'!D10) -> 0 | H14: kWh/yr
B16: Lifts (kWh) | C16: Quantity | D16: Unit
B17: Reference Lift Height | C17: ='Inputs Residential & Mixed-Use'!D15 -> 0 | D17: m | F17: Lift Height | G17: ='Inputs Residential & Mixed-Use'!D15 -> 0 | H17: m
B18: No. of Lifts | C18: ='Inputs Residential & Mixed-Use'!D14 -> 0 | F18: No. of Lifts | G18: ='Inputs Residential & Mixed-Use'!D14 -> 0
B20: Reference Lift Energy Use | C20: =(((110000*((C17/2)/1)*10)/3600)+0.07*24*365)*C18 -> 0 | D20: kWh/yr | G20: =(((110000*((G17/2)/1)*10)/3600)+0.07*24*365)*G18 -> 0 | H20: kWh/yr

Sheet Calculations C&S
B2: Carpark Ventilation (kWh) | C2: Quantity | D2: Unit | G2: Quantity | H2: Unit
B4: Reference Ventilation | C4: ='Inputs Residential & Mixed-Use'!D12*42.33*(3212/8760) -> 0 | D4: kWh/yr | F4: Heating & Cooling Energy Use | G4: ='Inputs Residential & Mixed-Use'!D12*42.33*(3212/8760) -> 0 | H4: kWh/yr
B6: Lighting Carpark (kWh) | C6: Quantity | D6: Unit | G6: Quantity | H6: Unit
B7: Reference Lighting Power Density | C7: 2 | D7: W/m2 | F7: Lighting Power Density | G7: 2 | H7: W/m2
B8: Hours of Operation per Day | C8: 10 | D8: hours | F8: Hours of Operation per Day (Living) | G8: 10 | H8: hours
B10: Reference Lighting Energy Use | C10: =(C7/1000)*C8*365*'Inputs Residential & Mixed-Use'!D12 -> 0 | D10: kWh/yr | F10: Lighting Energy Use | G10: =(G7/1000)*G8*365*'Inputs Residential & Mixed-Use'!D12 -> 0 | H10: kWh/yr
B12: Lighting Services (kWh) | C12: Quantity | D12: Unit | G12: Quantity | H12: Unit
B13: Reference Lighting Power Density | C13: 1.5 | D13: W/m2 | F13: Lighting Power Density | G13: 1.5 | H13: W/m2
B14: Hours of Operation per Day | C14: 4 | D14: hours | F14: Hours of Operation per Day (Living) | G14: 4 | H14: hours
B16: Reference Lighting Energy Use | C16: =(C13/1000)*C14*365*'Inputs Residential & Mixed-Use'!D13 -> 0 | D16: kWh/yr | F16: Lighting Energy Use | G16: =(G13/1000)*G14*365*'Inputs Residential & Mixed-Use'!D13 -> 0 | H16: kWh/yr

Sheet Totals Residential & Mixed-Use
H2: GHG Emission Factor Elec 2024 | J2: 0.86 | K2: Kg CO2/kWh | R2: Elec Price (normal) | T2: 0.289 | U2: $/kWh | W2: Gas Price | Y2: 0.035 | Z2: $/MJ
H3: GHG Emission Factor Gas | J3: 0.05153 | K3: Kg CO2/MJ | R3: Elec Price (GP) | T3: =T2+0.05 -> 0.339 | U3: $/kWh
H4: GP GHG emissions | J4: 0 | K4: Kg CO2/kWh
C6: Residential
C7: Energy Use (kWh/yr) | D7: Existing Building Stock | E7: Min. BCA 2022 Compliance | F7: ='Inputs Residential & Mixed-Use'!D5 -> 0 | H7: GHG Emissions (eqtCO2) | I7: Existing Building Stock | J7: Min. BCA 2022 Compliance | K7: ='Inputs Residential & Mixed-Use'!D5 -> 0 | M7: GHG Emissions (eqtCO2) With GP | N7: Existing Building Stock | O7: Min. BCA 2022 Compliance | P7: ='Inputs Residential & Mixed-Use'!D5 -> 0 | R7: Enery Cost | S7: Existing Building Stock | T7: Min. BCA 2022 Compliance | U7: ='Inputs Residential & Mixed-Use'!D5 -> 0 | W7: Energy Cost per Apt | X7: Existing Building Stock | Y7: Min. BCA 2022 Compliance | Z7: ='Inputs Residential & Mixed-Use'!D5 -> 0
C8: Heating & Cooling | D8: ='Calculations Residential'!C12 -> #N/A | E8: ='Calculations Residential'!G12 -> #N/A | F8: ='Calculations Residential'!K12 -> 0 | H8: =C8 -> Heating & Cooling | I8: =(D8*$J$2)/1000 -> #N/A | J8: =(E8*$J$2)/1000 -> #N/A | K8: =(F8*$J$2)/1000 -> 0 | M8: =H8 -> Heating & Cooling | N8: =I8 -> #N/A | O8: =(E8*$J$2)/1000 -> #N/A | P8: =IF('Inputs Residential & Mixed-Use'!$D$17="Whole Development",((F8*$J$4)/1000),((F8*$J$2)/1000)) -> 0 | R8: =C8 -> Heating & Cooling | S8: =D8*$T$2 -> #N/A | T8: =E8*$T$2 -> #N/A | U8: =IF('Inputs Residential & Mixed-Use'!$D$17="Whole Development",'Totals Residential & Mixed-Use'!F8*$T$3, 'Totals Residential & Mixed-Use'!F8*$T$2) -> 0 | W8: =R8 -> Heating & Cooling | X8: =S8/'Inputs Residential & Mixed-Use'!$D$6 -> #N/A | Y8: =T8/'Inputs Residential & Mixed-Use'!$D$6 -> #N/A | Z8: =U8/'Inputs Residential & Mixed-Use'!$D$6 -> #DIV/0!
C9: Appliances | D9: ='Calculations Residential'!C18 -> 0 | E9: ='Calculations Residential'!G18 -> 0 | F9: ='Calculations Residential'!K18 -> 0 | H9: =C9 -> Appliances | I9: =(D9*$J$2)/1000 -> 0 | J9: =(E9*$J$2)/1000 -> 0 | K9: =(F9*$J$2)/1000 -> 0 | M9: =H9 -> Appliances | N9: =I9 -> 0 | O9: =(E9*$J$2)/1000 -> 0 | P9: =IF('Inputs Residential & Mixed-Use'!$D$17="Whole Development",((F9*$J$4)/1000),((F9*$J$2)/1000)) -> 0 | R9: =C9 -> Appliances | S9: =D9*$T$2 -> 0 | T9: =E9*$T$2 -> 0 | U9: =IF('Inputs Residential & Mixed-Use'!$D$17="Whole Development",'Totals Residential & Mixed-Use'!F9*$T$3, 'Totals Residential & Mixed-Use'!F9*$T$2) -> 0 | W9: =R9 -> Appliances | X9: =S9/'Inputs Residential & Mixed-Use'!$D$6 -> #DIV/0! | Y9: =T9/'Inputs Residential & Mixed-Use'!$D$6 -> #DIV/0! | Z9: =U9/'Inputs Residential & Mixed-Use'!$D$6 -> #DIV/0!
C10: Lighting | D10: ='Calculations Residential'!C25 -> 0 | E10: ='Calculations Residential'!G25 -> 0 | F10: ='Calculations Residential'!K25 -> 0 | H10: =C10 -> Lighting | I10: =(D10*$J$2)/1000 -> 0 | J10: =(E10*$J$2)/1000 -> 0 | K10: =(F10*$J$2)/1000 -> 0 | M10: =H10 -> Lighting | N10: =I10 -> 0 | O10: =(E10*$J$2)/1000 -> 0 | P10: =IF('Inputs Residential & Mixed-Use'!$D$17="Whole Development",((F10*$J$4)/1000),((F10*$J$2)/1000)) -> 0 | R10: =C10 -> Lighting | S10: =D10*$T$2 -> 0 | T10: =E10*$T$2 -> 0 | U10: =IF('Inputs Residential & Mixed-Use'!$D$17="Whole Development",'Totals Residential & Mixed-Use'!F10*$T$3, 'Totals Residential & Mixed-Use'!F10*$T$2) -> 0 | W10: =R10 -> Lighting | X10: =S10/'Inputs Residential & Mixed-Use'!$D$6 -> #DIV/0! | Y10: =T10/'Inputs Residential & Mixed-Use'!$D$6 -> #DIV/0! | Z10: =U10/'Inputs Residential & Mixed-Use'!$D$6 -> #DIV/0!
C11: Hot Water | D11: ='Calculations Residential'!C37/3.6 -> 0 | E11: ='Calculations Residential'!G37 -> 0 | F11: ='Calculations Residential'!K37 -> #N/A | H11: =C11 -> Hot Water | I11: =(D11*3.6*$J$3)/1000 -> 0 | J11: =(E11*$J$2)/1000 -> 0 | K11: =(F11*$J$2)/1000 -> #N/A | M11: =H11 -> Hot Water | N11: =I11 -> 0 | O11: =(E11*$J$2)/1000 -> 0 | P11: =IF('Inputs Residential & Mixed-Use'!$D$17="Whole Development",((F11*$J$4)/1000),((F11*$J$2)/1000)) -> #N/A | R11: =C11 -> Hot Water | S11: =D11*3.6*$Y$2 -> 0 | T11: =E11*$T$2 -> 0 | U11: =IF('Inputs Residential & Mixed-Use'!$D$17="Whole Development",'Totals Residential & Mixed-Use'!F11*$T$3, 'Totals Residential & Mixed-Use'!F11*$T$2) -> #N/A | W11: =R11 -> Hot Water | X11: =S11/'Inputs Residential & Mixed-Use'!$D$6 -> #DIV/0! | Y11: =T11/'Inputs Residential & Mixed-Use'!$D$6 -> #DIV/0! | Z11: =U11/'Inputs Residential & Mixed-Use'!$D$6 -> #N/A
C12: Cooktops | D12: ='Calculations Residential'!C44/3.6 -> 0 | E12: ='Calculations Residential'!G44 -> 0 | F12: =IF('Calculations Residential'!K40="Gas",'Calculations Residential'!K44*0.277776,'Calculations Residential'!K44) -> 0 | H12: =C12 -> Cooktops | I12: =(D12*3.6*$J$3)/1000 -> 0 | J12: =(E12*$J$2)/1000 -> 0 | K12: =(F12*$J$2)/1000 -> 0 | M12: =H12 -> Cooktops | N12: =I12 -> 0 | O12: =(E12*$J$2)/1000 -> 0 | P12: =IF('Inputs Residential & Mixed-Use'!$D$17="Whole Development",((F12*$J$4)/1000),((F12*$J$2)/1000)) -> 0 | R12: =C12 -> Cooktops | S12: =D12*3.6*$Y$2 -> 0 | T12: =E12*$T$2 -> 0 | U12: =IF('Inputs Residential & Mixed-Use'!$D$17="Whole Development",'Totals Residential & Mixed-Use'!F12*$T$3, 'Totals Residential & Mixed-Use'!F12*$T$2) -> 0 | W12: =R12 -> Cooktops | X12: =S12/'Inputs Residential & Mixed-Use'!$D$6 -> #DIV/0! | Y12: =T12/'Inputs Residential & Mixed-Use'!$D$6 -> #DIV/0! | Z12: =U12/'Inputs Residential & Mixed-Use'!$D$6 -> #DIV/0!
C13: Clothes Drying | D13: ='Calculations Residential'!C47 -> 0 | E13: ='Calculations Residential'!G47 -> 0 | F13: ='Calculations Residential'!K47 -> 0 | H13: =C13 -> Clothes Drying | I13: =(D13*$J$2)/1000 -> 0 | J13: =(E13*$J$2)/1000 -> 0 | K13: =(F13*$J$2)/1000 -> 0 | M13: =H13 -> Clothes Drying | N13: =I13 -> 0 | O13: =(E13*$J$2)/1000 -> 0 | P13: =IF('Inputs Residential & Mixed-Use'!$D$17="Whole Development",((F13*$J$4)/1000),((F13*$J$2)/1000)) -> 0 | R13: =C13 -> Clothes Drying | S13: =D13*$T$2 -> 0 | T13: =E13*$T$2 -> 0 | U13: =IF('Inputs Residential & Mixed-Use'!$D$17="Whole Development",'Totals Residential & Mixed-Use'!F13*$T$3, 'Totals Residential & Mixed-Use'!F13*$T$2) -> 0 | W13: =R13 -> Clothes Drying | X13: =S13/'Inputs Residential & Mixed-Use'!$D$6 -> #DIV/0! | Y13: =T13/'Inputs Residential & Mixed-Use'!$D$6 -> #DIV/0! | Z13: =U13/'Inputs Residential & Mixed-Use'!$D$6 -> #DIV/0!
W14: Individual Solar PV | X14: =0 -> 0 | Y14: =0 -> 0 | Z14: =IF('Inputs Residential & Mixed-Use'!D40=0,('Inputs Residential & Mixed-Use'!D41*T2*-1),0) -> 0
C15: Total | D15: =SUM(D8:D13) -> #N/A | E15: =SUM(E8:E13) -> #N/A | F15: =SUM(F8:F13) -> #N/A | H15: =C15 -> Total | I15: =SUM(I8:I13) -> #N/A | J15: =SUM(J8:J13) -> #N/A | K15: =SUM(K8:K13) -> #N/A | M15: =H15 -> Total | N15: =SUM(N8:N13) -> #N/A | O15: =SUM(O8:O13) -> #N/A | P15: =SUM(P8:P13) -> #N/A | R15: =C15 -> Total | S15: =SUM(S8:S13) -> #N/A | T15: =SUM(T8:T13) -> #N/A | U15: =SUM(U8:U13) -> #N/A | W15: =R15 -> Total | X15: =SUM(X8:X13) -> #N/A | Y15: =SUM(Y8:Y13) -> #N/A | Z15: =SUM(Z8:Z13) -> #DIV/0!
C16: Reduction compared to minimum BCA 2022 | F16: =(E15-F15) -> #N/A
W17: Annual Operational Cost Reduction | X17: =X15-Z15 -> #N/A | Y17: =Y15-Z15 -> #N/A
C18: Communal Areas
C19: Energy Use (kWh/yr) | E19: Min. BCA 2022 Compliance | F19: ='Inputs Residential & Mixed-Use'!D5 -> 0 | H19: GHG Emissions (eqtCO2) | J19: Min. BCA 2022 Compliance | K19: ='Inputs Residential & Mixed-Use'!D5 -> 0 | M19: GHG Emissions (eqtCO2) With GP | O19: Min. BCA 2022 Compliance | P19: ='Inputs Residential & Mixed-Use'!D5 -> 0 | R19: Enery Cost | T19: Min. BCA 2022 Compliance | U19: ='Inputs Residential & Mixed-Use'!D5 -> 0
C20: Heating & Cooling | E20: ='Calculations Communal'!C8 -> #N/A | F20: ='Calculations Communal'!G8 -> #N/A | H20: =C20 -> Heating & Cooling | J20: =E20*$J$2/1000 -> #N/A | K20: =(F20*$J$2)/1000 -> #N/A | M20: =H20 -> Heating & Cooling | O20: =E20*$J$2/1000 -> #N/A | P20: =IF('Inputs Residential & Mixed-Use'!$D$17="Whole Development",F20*$J$4/1000, IF('Inputs Residential & Mixed-Use'!$D$17="Base Building",F20*$J$4/1000,F20*$J$2/1000)) -> #N/A | R20: =C20 -> Heating & Cooling | T20: =E20*$T$2 -> #N/A | U20: =F20*$T$2 -> #N/A
C21: Lighting | E21: ='Calculations Communal'!C14 -> 0 | F21: ='Calculations Communal'!G14 -> 0 | H21: =C21 -> Lighting | J21: =E21*$J$2/1000 -> 0 | K21: =(F21*$J$2)/1000 -> 0 | M21: =H21 -> Lighting | O21: =E21*$J$2/1000 -> 0 | P21: =IF('Inputs Residential & Mixed-Use'!$D$17="Whole Development",F21*$J$4/1000, IF('Inputs Residential & Mixed-Use'!$D$17="Base Building",F21*$J$4/1000,F21*$J$2/1000)) -> 0 | R21: =C21 -> Lighting | T21: =E21*$T$2 -> 0 | U21: =F21*$T$2 -> 0
C22: Lifts | E22: ='Calculations Communal'!C20 -> 0 | F22: ='Calculations Communal'!G20 -> 0 | H22: =C22 -> Lifts | J22: =E22*$J$2/1000 -> 0 | K22: =(F22*$J$2)/1000 -> 0 | M22: =H22 -> Lifts | O22: =E22*$J$2/1000 -> 0 | P22: =IF('Inputs Residential & Mixed-Use'!$D$17="Whole Development",F22*$J$4/1000, IF('Inputs Residential & Mixed-Use'!$D$17="Base Building",F22*$J$4/1000,F22*$J$2/1000)) -> 0 | R22: =C22 -> Lifts | T22: =E22*$T$2 -> 0 | U22: =F22*$T$2 -> 0
C23: Total | E23: =SUM(E21:E22) -> 0 | F23: =SUM(F21:F22) -> 0 | H23: Total | J23: =SUM(J20:J22) -> #N/A | K23: =SUM(K20:K22) -> #N/A | M23: Total | O23: =SUM(O20:O22) -> #N/A | P23: =SUM(P20:P22) -> #N/A | R23: =C23 -> Total | T23: =SUM(T20:T22) -> #N/A | U23: =SUM(U20:U22) -> #N/A
C25: Retail
C26: Energy Use (kWh/yr) | E26: Min. BCA 2022 Compliance | F26: ='Inputs Residential & Mixed-Use'!D5 -> 0 | H26: GHG Emissions (eqtCO2) | J26: Min. BCA 2022 Compliance | K26: ='Inputs Residential & Mixed-Use'!D5 -> 0 | M26: GHG Emissions (eqtCO2) With GP | O26: Min. BCA 2022 Compliance | P26: ='Inputs Residential & Mixed-Use'!D5 -> 0 | R26: Energy Cost | T26: Min. BCA 2022 Compliance | U26: ='Inputs Residential & Mixed-Use'!D5 -> 0
C27: Heating & Cooling (Elec) | E27: ='Calculations Retail'!C9 -> #N/A | F27: ='Calculations Retail'!G9 -> #N/A | H27: =C27 -> Heating & Cooling (Elec) | J27: =(E27*$J$2)/1000 -> #N/A | K27: =(F27*$J$2)/1000 -> #N/A | M27: =H27 -> Heating & Cooling (Elec) | O27: =(E27*$J$2)/1000 -> #N/A | P27: =IF('Inputs Residential & Mixed-Use'!$D$17="Whole Development",((F27*$J$4)/1000),((F27*$J$2)/1000)) -> #N/A | R27: =C27 -> Heating & Cooling (Elec) | T27: =E27*$T$2 -> #N/A | U27: =F27*$T$2 -> #N/A
C28: Heating & Cooling (Gas) | E28: ='Calculations Retail'!C17*0.277776 -> 0 | F28: ='Calculations Retail'!G17*0.2777776 -> 0 | H28: Heating & Cooling (Gas) | J28: =('Calculations Retail'!C17*J3)/1000 -> 0 | K28: =(F28*3.6*J3)/1000 -> 0 | M28: Heating & Cooling (Gas) | O28: =J28 -> 0 | P28: =K28 -> 0 | R28: Heating & Cooling (Gas) | T28: ='Calculations Retail'!K17*$Y$2 -> 0 | U28: ='Calculations Retail'!O17*$Y$2 -> 0
C29: Fans | E29: ='Calculations Retail'!C21 -> 0 | F29: ='Calculations Retail'!G21 -> 0 | H29: Fans | J29: =(E29*$J$2)/1000 -> 0 | K29: =(F29*$J$2)/1000 -> 0 | M29: Fans | O29: =(E29*$J$2)/1000 -> 0 | P29: =IF('Inputs Residential & Mixed-Use'!$D$17="Whole Development",((F29*$J$4)/1000),((F29*$J$2)/1000)) -> 0 | R29: Fans | T29: =E29*$T$2 -> 0 | U29: =F29*$T$2 -> 0
C30: Lighting | E30: ='Calculations Retail'!C27 -> 0 | F30: ='Calculations Retail'!G27 -> 0 | H30: =C30 -> Lighting | J30: =(E30*$J$2)/1000 -> 0 | K30: =(F30*$J$2)/1000 -> 0 | M30: =H30 -> Lighting | O30: =(E30*$J$2)/1000 -> 0 | P30: =IF('Inputs Residential & Mixed-Use'!$D$17="Whole Development",((F30*$J$4)/1000),((F30*$J$2)/1000)) -> 0 | R30: =C30 -> Lighting | T30: =E30*$T$2 -> 0 | U30: =F30*$T$2 -> 0
C31: Hot Water | E31: ='Calculations Retail'!C38 -> 0 | F31: ='Calculations Retail'!G38 -> 0 | H31: =C31 -> Hot Water | J31: =(E31*$J$2)/1000 -> 0 | K31: =(F31*$J$2)/1000 -> 0 | M31: =H31 -> Hot Water | O31: =(E31*$J$2)/1000 -> 0 | P31: =IF('Inputs Residential & Mixed-Use'!$D$17="Whole Development",((F31*$J$4)/1000),((F31*$J$2)/1000)) -> 0 | R31: =C31 -> Hot Water | T31: =E31*$T$2 -> 0 | U31: =F31*$T$2 -> 0
C32: Cooktops | E32: ='Calculations Retail'!C46*0.277776 -> 17519.888 | F32: =IF('Calculations Retail'!G42="Gas",'Calculations Retail'!G46*0.277776,'Calculations Retail'!G46) -> #N/A | H32: =C32 -> Cooktops | J32: =(E32*3.6*$J$3)/1000 -> 3.2500794 | K32: =IF('Calculations Retail'!G42="Gas",((F32*3.6*$J$3)/1000),((F32*$J$2)/1000)) -> #N/A | M32: =H32 -> Cooktops | O32: =(E32*$J$3)/1000 -> 0.90279982 | P32: =IF('Calculations Retail'!G42="Gas",(J32),IF('Inputs Residential & Mixed-Use'!D17="Whole Development",((F32*$J$4)/1000),((F32*$J$2)/1000))) -> #N/A | R32: =C32 -> Cooktops | T32: =E32*3.6*$Y$2 -> 2207.5059 | U32: =IF('Calculations Retail'!G42="Gas",'Totals Residential & Mixed-Use'!F32*3.6*'Totals Residential & Mixed-Use'!Y2,'Totals Residential & Mixed-Use'!F32*$T$2) -> #N/A
C33: Total | E33: =SUM(E27:E32) -> #N/A | F33: =SUM(F27:F32) -> #N/A | H33: =C33 -> Total | J33: =SUM(J27:J32) -> #N/A | K33: =SUM(K27:K32) -> #N/A | M33: =H33 -> Total | O33: =SUM(O27:O32) -> #N/A | P33: =SUM(P27:P32) -> #N/A | R33: =C33 -> Total | T33: =E33*$T$2 -> #N/A | U33: =F33*$T$2 -> #N/A
C35: Office
C36: Energy Use (kWh/yr) | E36: Min. BCA 2022 Compliance | F36: ='Inputs Residential & Mixed-Use'!D5 -> 0 | H36: GHG Emissions (eqtCO2) | J36: Min. BCA 2022 Compliance | K36: ='Inputs Residential & Mixed-Use'!D5 -> 0 | M36: GHG Emissions (eqtCO2) With GP | O36: Min. BCA 2022 Compliance | P36: ='Inputs Residential & Mixed-Use'!D5 -> 0 | R36: Energy Cost | T36: Min. BCA 2022 Compliance | U36: ='Inputs Residential & Mixed-Use'!D5 -> 0
C37: Heating & Cooling (Elec) | E37: ='Calculations Office'!C9 -> #N/A | F37: ='Calculations Office'!G9 -> #N/A | H37: =C37 -> Heating & Cooling (Elec) | J37: =(E37*$J$2)/1000 -> #N/A | K37: =(F37*$J$2)/1000 -> #N/A | M37: =H37 -> Heating & Cooling (Elec) | O37: =(E37*$J$2)/1000 -> #N/A | P37: =IF('Inputs Residential & Mixed-Use'!$D$17="Whole Development",((F37*$J$4)/1000),((F37*$J$2)/1000)) -> #N/A | R37: =C37 -> Heating & Cooling (Elec) | T37: =E37*$T$2 -> #N/A | U37: =F37*$T$2 -> #N/A
C38: Heating & Cooling (Gas) | E38: ='Calculations Office'!C17*0.277776 -> 0 | F38: ='Calculations Office'!G17*0.277776 -> 0 | H38: =C38 -> Heating & Cooling (Gas) | J38: =('Calculations Office'!G17*J3)/1000 -> 0 | K38: =(F38*3.6*J3)/1000 -> 0 | M38: =H38 -> Heating & Cooling (Gas) | O38: =J38 -> 0 | P38: =K38 -> 0 | R38: =C38 -> Heating & Cooling (Gas) | T38: ='Calculations Office'!K17*Y2 -> 0 | U38: ='Calculations Office'!O17*Y2 -> 0
C39: Fans | E39: ='Calculations Office'!C21 -> 0 | F39: ='Calculations Office'!G21 -> 0 | H39: Fans | J39: =(E39*$J$2)/1000 -> 0 | K39: =(F39*$J$2)/1000 -> 0 | M39: Fans | O39: =(E39*$J$2)/1000 -> 0 | P39: =IF('Inputs Residential & Mixed-Use'!$D$17="Whole Development",((F39*$J$4)/1000),((F39*$J$2)/1000)) -> 0 | R39: Fans | T39: =E39*$T$2 -> 0 | U39: =F39*$T$2 -> 0
C40: Appliances | E40: ='Calculations Office'!C27 -> 0 | F40: ='Calculations Office'!G27 -> 0 | H40: =C40 -> Appliances | J40: =(E40*$J$2)/1000 -> 0 | K40: =(F40*$J$2)/1000 -> 0 | M40: =H40 -> Appliances | O40: =(E40*$J$2)/1000 -> 0 | P40: =IF('Inputs Residential & Mixed-Use'!$D$17="Whole Development",((F40*$J$4)/1000),((F40*$J$2)/1000)) -> 0 | R40: =C40 -> Appliances | T40: =E40*$T$2 -> 0 | U40: =F40*$T$2 -> 0
C41: Lighting | E41: ='Calculations Office'!C33 -> 0 | F41: ='Calculations Office'!G33 -> 0 | H41: =C41 -> Lighting | J41: =(E41*$J$2)/1000 -> 0 | K41: =(F41*$J$2)/1000 -> 0 | M41: =H41 -> Lighting | O41: =(E41*$J$2)/1000 -> 0 | P41: =IF('Inputs Residential & Mixed-Use'!$D$17="Whole Development",((F41*$J$4)/1000),((F41*$J$2)/1000)) -> 0 | R41: =C41 -> Lighting | T41: =E41*$T$2 -> 0 | U41: =F41*$T$2 -> 0
C42: Hot Water | E42: ='Calculations Office'!C44 -> 0 | F42: ='Calculations Office'!G44 -> 0 | H42: =C42 -> Hot Water | J42: =(E42*$J$2)/1000 -> 0 | K42: =(F42*$J$2)/1000 -> 0 | M42: =H42 -> Hot Water | O42: =(E42*$J$2)/1000 -> 0 | P42: =IF('Inputs Residential & Mixed-Use'!$D$17="Whole Development",((F42*$J$4)/1000),((F42*$J$2)/1000)) -> 0 | R42: =C42 -> Hot Water | T42: =E42*$T$2 -> 0 | U42: =F42*$T$2 -> 0
C43: Total | E43: =SUM(E37:E42) -> #N/A | F43: =SUM(F37:F42) -> #N/A | H43: =C43 -> Total | J43: =SUM(J37:J42) -> #N/A | K43: =SUM(K37:K42) -> #N/A | M43: =H43 -> Total | O43: =SUM(O37:O42) -> #N/A | P43: =SUM(P37:P42) -> #N/A | R43: =C43 -> Total | T43: =E43 -> #N/A | U43: =F43 -> #N/A
C45: Carpark & Services
...

Sheet Drop down
J2: Total ACE MJ/m2
J3: 3 | K3: 7 | L3: 7.5 | M3: 8
B4: Type of HVAC system (resi) | C4: Standard COP | I4: FR Climate Zone | J4: 3 | K4: 7 | L4: 7.5 | M4: 8
B5: Split system | C5: 3.1 | I5: 21 Melbourne | J5: 199 | K5: 62 | L5: 52 | M5: 44
B6: VRV/VRF | C6: 3.3 | I6: 60 Tullamarine | J6: 279 | K6: 55 | L6: 47 | M6: 37
B7: Hydronic heating (heat pump) | C7: 2.5 | I7: 62 Moorabbin Airport | J7: 262 | K7: 99 | L7: 84 | M7: 69
B8: Hydronic heating (gas) | C8: 0.8
I9: Climate Zone | J9: Retail | K9: Office | L9: Communal Areas
I10: 6 | J10: =Averages!H12 -> 28.223452 | K10: 16.7 | L10: 20
B11: Hot water system | C11: Standard COP | I11: 7
B12: Heat pump | C12: 2.5
B13: Electric Instantaeous | C13: 1
B14: Gas | C14: 0.8 | I14: Carbon Neutral
I15: Whole Development
B16: Cooktops | C16: Standard Energy use | D16: Commercial Kitchen | E16: Column1 | I16: Base Building
B17: Electric induction | C17: 0.35 | D17: 3.5 | E17: kW/h
B18: Electric convection | C18: =C17*1.1 -> 0.385 | D18: 25 | E18: kW/h
B19: Gas | C19: 6 | D19: =2*14.4 -> 28.8 | E19: MJ/hr
B20: None | C20: 0 | D20: 0 | E20: kW/h
B22: Type of HVAC system retail | C22: COP
B23: Split system | C23: 3.1
B24: VRV/VRF | C24: 3.4

Sheet Averages
B3: Retail | C3: Area (m2) | D3: Heating (kWh) | E3: Cooling (kWh) | F3: Heating (kWhm2) | G3: Cooling (kWh/m2) | H3: Total H&C (kWh/m2) | K3: Educational | L3: Area (m2) | M3: Heating (kWh) | N3: Cooling (kWh) | O3: Heating (kWhm2) | P3: Cooling (kWh/m2) | Q3: Total H&C (kWh/m2)
B4: 786-794 Nicholson St, Fitzroy | C4: 184 | D4: 5460.52 | E4: 2316.9 | F4: =D4/C4 -> 29.676739 | G4: =E4/C4 -> 12.591848 | H4: =SUM(D4:E4)/C4 -> 42.268587 | K4: Kolbe | L4: 2119.31 | M4: 46633.8 | N4: 17577.3 | O4: =M4/L4 -> 22.004237 | P4: =N4/L4 -> 8.2938787 | Q4: =O4+P4 -> 30.298116
B5: 303 Collins St, Melbourne | C5: 2272 | D5: 51882 | E5: 9964 | F5: =D5/C5 -> 22.835387 | G5: =E5/C5 -> 4.3855634 | H5: =SUM(D5:E5)/C5 -> 27.220951 | K5: Eastborne Primary | L5: 544 | M5: 1711 | N5: 1391 | O5: =M5/L5 -> 3.1452206 | P5: =N5/L5 -> 2.5569853 | Q5: =O5+P5 -> 5.7022059
B6: 22 Black St | C6: 35.3 | D6: 261.29 | E6: 1171.36 | F6: =D6/C6 -> 7.401983 | G6: =E6/C6 -> 33.183003 | H6: =SUM(D6:E6)/C6 -> 40.584986 | K6: St Joseph's College | L6: 2864 | M6: 23637 | N6: 11480 | O6: =M6/L6 -> 8.2531425 | P6: =N6/L6 -> 4.0083799 | Q6: =O6+P6 -> 12.261522
B7: 846-858 Glenferrie Rd, Hawthorn | C7: 1038 | D7: 2692 | E7: 9544 | F7: =D7/C7 -> 2.5934489 | G7: =E7/C7 -> 9.194605 | H7: =SUM(D7:E7)/C7 -> 11.788054 | K7: McKinnon Primary | L7: 753 | M7: 1635 | N7: 6879 | O7: =M7/L7 -> 2.1713147 | P7: =N7/L7 -> 9.1354582 | Q7: =O7+P7 -> 11.306773
B8: 8 Egan St | C8: 311 | D8: 2808 | E8: 855 | F8: =D8/C8 -> 9.0289389 | G8: =E8/C8 -> 2.7491961 | H8: =SUM(D8:E8)/C8 -> 11.778135 | K8: Clayton South Primary | L8: 1224 | M8: 4523 | N8: 9481 | O8: =M8/L8 -> 3.6952614 | P8: =N8/L8 -> 7.745915 | Q8: =O8+P8 -> 11.441176
B9: 35-37 Mount St | C9: 50 | D9: 1282 | E9: 503 | F9: =D9/C9 -> 25.64 | G9: =E9/C9 -> 10.06 | H9: =SUM(D9:E9)/C9 -> 35.7 | K9: Gisborne Secondary | L9: 452 | M9: 2109 | N9: 1663 | O9: =M9/L9 -> 4.6659292 | P9: =N9/L9 -> 3.6792035 | Q9: =O9+P9 -> 8.3451327
F10: =D10/C10 -> #DIV/0! | G10: =E10/C10 -> #DIV/0! | H10: =SUM(D10:E10)/C10 -> #DIV/0! | K10: Casey Central Primary | L10: 878 | M10: 3288 | N10: 4284 | O10: =M10/L10 -> 3.7448747 | P10: =N10/L10 -> 4.8792711 | Q10: =O10+P10 -> 8.6241458
F11: =D11/C11 -> #DIV/0! | G11: =E11/C11 -> #DIV/0! | H11: =SUM(D11:E11)/C11 -> #DIV/0! | K11: Clyde Creek North Primary | L11: =1001+1001+1001+1562+1403 -> 5968 | M11: =3921+3932+3985+5406+1836 -> 19080 | N11: =3685+3659+3526+5950+882+873 -> 18575 | O11: =M11/L11 -> 3.1970509 | P11: =N11/L11 -> 3.112433 | Q11: =O11+P11 -> 6.3094839
G12: Average | H12: =AVERAGE(H4:H9) -> 28.223452 | K12: Clyde North | L12: =878+1083+1083+1485+1338 -> 5867 | M12: =3283+4159+4176+5549+6437+1439 -> 25043 | N12: =4334+6148+5966+5925+6873 -> 29246 | O12: =M12/L12 -> 4.2684507 | P12: =N12/L12 -> 4.9848304 | Q12: =O12+P12 -> 9.2532811
B14: Office | C14: Area (m2) | D14: Heating (kWh) | E14: Cooling (kWh) | F14: Heating (kWhm2) | G14: Cooling (kWh/m2) | H14: Total H&C (kWh/m2)
B15: 14 Martin St, Heidelberg Rd | C15: 2553 | D15: 14465 | E15: 9529 | F15: =D15/C15 -> 5.6658833 | G15: =E15/C15 -> 3.7324716 | H15: =SUM(D15:E15)/C15 -> 9.3983549 | P15: Average | Q15: =AVERAGE(Q4:Q12) -> 11.504649
B16: 14-18 Smith St | C16: 487 | D16: 19993 | E16: 5473 | F16: =D16/C16 -> 41.053388 | G16: =E16/C16 -> 11.238193 | H16: =SUM(D16:E16)/C16 -> 52.291581
B17: 13-19 Amsterdam St | C17: 766.42 | D17: 15848.1 | E17: 12766.6 | F17: =D17/C17 -> 20.678088 | G17: =E17/C17 -> 16.657446 | H17: =SUM(D17:E17)/C17 -> 37.335534 | K17: Student accomodation | L17: Area (m2) | M17: Heating (kWh) | N17: Cooling (kWh) | O17: Heating (kWhm2) | P17: Cooling (kWh/m2) | Q17: Total H&C (kWh/m2)
B18: 17-23 Wangaratta St | C18: 1950 | D18: 7359 | E18: 7757 | F18: =D18/C18 -> 3.7738462 | G18: =E18/C18 -> 3.9779487 | H18: =SUM(D18:E18)/C18 -> 7.7517949 | K18: 100-102 Bouverie St | L18: 255 | M18: 4682 | N18: 4504 | O18: =M18/L18 -> 18.360784 | P18: =N18/L18 -> 17.662745 | Q18: =O18+P18 -> 36.023529
B19: 71-89 Moorabool St | C19: 1233 | D19: 9205 | E19: 3387 | F19: =D19/C19 -> 7.4655312 | G19: =E19/C19 -> 2.7469586 | H19: =SUM(D19:E19)/C19 -> 10.21249 | K19: 204-206 King St | L19: 24738 | M19: 583198 | N19: 212362 | O19: =M19/L19 -> 23.574986 | P19: =N19/L19 -> 8.584445 | Q19: =O19+P19 -> 32.159431
B20: 167-169 Cremorne St | C20: 2925 | D20: 23838 | E20: 26637 | F20: =D20/C20 -> 8.1497436 | G20: =E20/C20 -> 9.1066667 | H20: =SUM(D20:E20)/C20 -> 17.25641 | K20: 43 Mackenzie St | L20: 16636 | M20: 692119 | N20: 49460 | O20: =M20/L20 -> 41.603691 | P20: =N20/L20 -> 2.9730704 | Q20: =O20+P20 -> 44.576761
B21: 18-20 Rutland St | C21: 1039 | D21: 4541 | E21: 3915 | F21: =D21/C21 -> 4.3705486 | G21: =E21/C21 -> 3.7680462 | H21: =SUM(D21:E21)/C21 -> 8.1385948 | K21: 21-25 Bouverie St | L21: 10863 | M21: 156227.52 | N21: 76199.3 | O21: =M21/L21 -> 14.381618 | P21: =N21/L21 -> 7.0145724 | Q21: =O21+P21 -> 21.396191
B22: 85 Dover St | C22: 397 | D22: 2053 | E22: 1693 | F22: =D22/C22 -> 5.1712846 | G22: =E22/C22 -> 4.2644836 | H22: =SUM(D22:E22)/C22 -> 9.4357683
B23: 40-50 Rokeby St | C23: 766.42 | D23: 2769.3 | E23: 4953.6 | F23: =D23/C23 -> 3.613293 | G23: =E23/C23 -> 6.4632969 | H23: =SUM(D23:E23)/C23 -> 10.07659 | P23: Average | Q23: =AVERAGE(Q18:Q21) -> 33.538978
B24: 30 Cambridge St | C24: 449 | D24: 1854 | E24: 2041 | F24: =D24/C24 -> 4.1291759 | G24: =E24/C24 -> 4.545657 | H24: =SUM(D24:E24)/C24 -> 8.674833
B25: 32-38 Rokeby St | C25: 3835.6 | D25: 27756.3 | E25: 29468.9 | F25: =D25/C25 -> 7.2364949 | G25: =E25/C25 -> 7.6829961 | H25: =SUM(D25:E25)/C25 -> 14.919491
B26: 46 Gwynne St | C26: 116 | D26: 827 | E26: 913 | F26: =D26/C26 -> 7.1293103 | G26: =E26/C26 -> 7.8706897 | H26: =SUM(D26:E26)/C26 -> 15
G28: Average | H28: =AVERAGE(H15:H26) -> 16.70762
B31: Aged Care | C31: Area (m2) | D31: Heating (kWh) | E31: Cooling (kWh) | F31: Heating (kWhm2) | G31: Cooling (kWh/m2) | H31: Total H&C (kWh/m2)
B32: Romsey Aged Care | C32: 8233 | D32: 162744 | E32: 23443 | F32: =D32/C32 -> 19.767278 | G32: =E32/C32 -> 2.8474432 | H32: =F32+G32 -> 22.614721
B33: 102 Shrives Rd | C33: 10179 | D33: 233638 | E33: 33225 | F33: =D33/C33 -> 22.952942 | G33: =E33/C33 -> 3.2640731 | H33: =F33+G33 -> 26.217015
B34: 20 Tivendale Rd | C34: 8798 | D34: 249184 | E34: 22862 | F34: =D34/C34 -> 28.322801 | G34: =E34/C34 -> 2.5985451 | H34: =F34+G34 -> 30.921346
B35: 175 MacMahons Rd | C35: 6340 | D35: 830914 | E35: 36729 | F35: =D35/C35 -> 131.05899 | G35: =E35/C35 -> 5.7932177 | H35: =F35+G35 -> 136.85221
B36: 52 Golf Rd | C36: 1633 | D36: 39991 | E36: 8051 | F36: =D36/C36 -> 24.489284 | G36: =E36/C36 -> 4.9301898 | H36: =F36+G36 -> 29.419473
B37: 1505 Point Nepean | C37: 16184 | D37: 488511 | E37: 36008 | F37: =D37/C37 -> 30.184812 | G37: =E37/C37 -> 2.2249135 | H37: =F37+G37 -> 32.409726
F38: =D38/C38 -> #DIV/0! | G38: =E38/C38 -> #DIV/0! | H38: =F38+G38 -> #DIV/0!
G40: Average | H40: =AVERAGE(H32:H34,H36:H37) -> 28.316456
